/home/anderson/virtenvs/omega/local/lib/python2.7/site-packages/kronos/__init__.py:11: RemovedInDjango19Warning: django.utils.importlib will be removed in Django 1.9.
  from django.utils.importlib import import_module

[19/Sep/2015 15:14:26]"GET / HTTP/1.1" 200 3692
[19/Sep/2015 15:14:31]"GET / HTTP/1.1" 200 3692
[19/Sep/2015 15:14:32]"GET /static/lib/bootstrap/css/bootstrap.css HTTP/1.1" 304 0
[19/Sep/2015 15:14:32]"GET /static/css/omega.css HTTP/1.1" 304 0
[19/Sep/2015 15:14:32]"GET /static/img/omega.png HTTP/1.1" 304 0
[19/Sep/2015 15:14:32]"GET /static/lib/font-awesome/css/font-awesome.css HTTP/1.1" 304 0
[19/Sep/2015 15:14:32]"GET / HTTP/1.1" 200 3692
[19/Sep/2015 15:14:32]"GET /static/lib/bootstrap/css/bootstrap.css HTTP/1.1" 304 0
[19/Sep/2015 15:14:32]"GET /static/css/omega.css HTTP/1.1" 304 0
[19/Sep/2015 15:14:32]"GET /static/lib/font-awesome/css/font-awesome.css HTTP/1.1" 304 0
[19/Sep/2015 15:14:32]"GET /static/img/omega.png HTTP/1.1" 304 0
[19/Sep/2015 15:14:33]"GET / HTTP/1.1" 200 3692
[19/Sep/2015 15:14:33]"GET /static/lib/bootstrap/css/bootstrap.css HTTP/1.1" 304 0
[19/Sep/2015 15:14:33]"GET /static/css/omega.css HTTP/1.1" 304 0
[19/Sep/2015 15:14:33]"GET /static/lib/font-awesome/css/font-awesome.css HTTP/1.1" 304 0
[19/Sep/2015 15:14:33]"GET /static/img/omega.png HTTP/1.1" 304 0
[19/Sep/2015 15:14:33]"GET / HTTP/1.1" 200 3692
[19/Sep/2015 15:14:33]"GET /static/lib/bootstrap/css/bootstrap.css HTTP/1.1" 304 0
[19/Sep/2015 15:14:33]"GET /static/css/omega.css HTTP/1.1" 304 0
[19/Sep/2015 15:14:33]"GET /static/lib/font-awesome/css/font-awesome.css HTTP/1.1" 304 0
[19/Sep/2015 15:14:33]"GET /static/img/omega.png HTTP/1.1" 304 0
[19/Sep/2015 15:14:33]"GET / HTTP/1.1" 200 3692
[19/Sep/2015 15:14:34]"GET /static/lib/bootstrap/css/bootstrap.css HTTP/1.1" 304 0
[19/Sep/2015 15:14:34]"GET /static/css/omega.css HTTP/1.1" 304 0
[19/Sep/2015 15:14:34]"GET /static/lib/font-awesome/css/font-awesome.css HTTP/1.1" 304 0
[19/Sep/2015 15:14:34]"GET /static/img/omega.png HTTP/1.1" 304 0
[19/Sep/2015 15:14:34]"GET / HTTP/1.1" 200 3692
[19/Sep/2015 15:14:34]"GET /static/img/omega.png HTTP/1.1" 304 0
[19/Sep/2015 15:14:34]"GET /static/lib/bootstrap/css/bootstrap.css HTTP/1.1" 304 0
[19/Sep/2015 15:14:34]"GET /static/lib/font-awesome/css/font-awesome.css HTTP/1.1" 304 0
[19/Sep/2015 15:14:34]"GET /static/css/omega.css HTTP/1.1" 304 0
[19/Sep/2015 15:14:34]"GET / HTTP/1.1" 200 3692
[19/Sep/2015 15:14:34]"GET /static/lib/bootstrap/css/bootstrap.css HTTP/1.1" 304 0
[19/Sep/2015 15:14:34]"GET /static/css/omega.css HTTP/1.1" 304 0
[19/Sep/2015 15:14:34]"GET /static/lib/font-awesome/css/font-awesome.css HTTP/1.1" 304 0
[19/Sep/2015 15:14:34]"GET /static/img/omega.png HTTP/1.1" 304 0
[19/Sep/2015 15:14:35]"GET / HTTP/1.1" 200 3692
[19/Sep/2015 15:14:35]"GET /static/lib/bootstrap/css/bootstrap.css HTTP/1.1" 304 0
[19/Sep/2015 15:14:35]"GET /static/img/omega.png HTTP/1.1" 304 0
[19/Sep/2015 15:14:35]"GET /static/lib/font-awesome/css/font-awesome.css HTTP/1.1" 304 0
[19/Sep/2015 15:14:35]"GET /static/css/omega.css HTTP/1.1" 304 0
[19/Sep/2015 15:14:35]"GET / HTTP/1.1" 200 3692
[19/Sep/2015 15:14:35]"GET /static/lib/bootstrap/css/bootstrap.css HTTP/1.1" 304 0
[19/Sep/2015 15:14:35]"GET /static/css/omega.css HTTP/1.1" 304 0
[19/Sep/2015 15:14:35]"GET /static/lib/font-awesome/css/font-awesome.css HTTP/1.1" 304 0
[19/Sep/2015 15:14:35]"GET /static/img/omega.png HTTP/1.1" 304 0
[19/Sep/2015 15:14:36]"GET / HTTP/1.1" 200 3692
[19/Sep/2015 15:14:36]"GET /static/lib/bootstrap/css/bootstrap.css HTTP/1.1" 304 0
[19/Sep/2015 15:14:36]"GET /static/lib/font-awesome/css/font-awesome.css HTTP/1.1" 304 0
[19/Sep/2015 15:14:36]"GET /static/img/omega.png HTTP/1.1" 304 0
[19/Sep/2015 15:14:36]"GET /static/css/omega.css HTTP/1.1" 304 0
[19/Sep/2015 15:14:36]"GET / HTTP/1.1" 200 3692
[19/Sep/2015 15:14:36]"GET /static/lib/font-awesome/css/font-awesome.css HTTP/1.1" 304 0
[19/Sep/2015 15:14:36]"GET /static/img/omega.png HTTP/1.1" 304 0
[19/Sep/2015 15:14:36]"GET /static/lib/bootstrap/css/bootstrap.css HTTP/1.1" 304 0
[19/Sep/2015 15:14:36]"GET /static/css/omega.css HTTP/1.1" 304 0
[19/Sep/2015 15:14:36]"GET / HTTP/1.1" 200 3692
- Broken pipe from ('127.0.0.1', 46958)
[19/Sep/2015 15:14:36]"GET / HTTP/1.1" 200 3692
[19/Sep/2015 15:14:36]"GET /static/css/omega.css HTTP/1.1" 304 0
[19/Sep/2015 15:14:36]"GET /static/img/omega.png HTTP/1.1" 304 0
[19/Sep/2015 15:14:36]"GET /static/lib/font-awesome/css/font-awesome.css HTTP/1.1" 304 0
[19/Sep/2015 15:14:36]"GET /static/lib/bootstrap/css/bootstrap.css HTTP/1.1" 304 0
/home/joseagraz/Escritorio/pdvsa-t-d/pdvsa/urls.py:8: RemovedInDjango19Warning: Default value of 'RedirectView.permanent' will change from True to False in Django 1.9. Set an explicit value to silence this warning.
  url(r'^$', RedirectView.as_view(url=reverse_lazy('login'))),

[10/Oct/2015 21:44:06] "GET /Login/ HTTP/1.1" 200 2122
[10/Oct/2015 21:44:06] "GET /static/css/bootstrap.min.css HTTP/1.1" 304 0
[10/Oct/2015 21:44:06] "GET /static/css/base.css HTTP/1.1" 304 0
[10/Oct/2015 21:44:06] "GET /static/css/login.css HTTP/1.1" 304 0
[10/Oct/2015 21:44:06] "GET /static/js/bootstrap.min.js HTTP/1.1" 304 0
[10/Oct/2015 21:44:06] "GET /static/js/jquery-1.11.2.min.js HTTP/1.1" 304 0
[10/Oct/2015 21:44:06] "GET /static/img/header_corazon.gif HTTP/1.1" 304 0
[10/Oct/2015 21:44:06] "GET /static/img/logo.png HTTP/1.1" 404 1649
[10/Oct/2015 21:44:06] "GET /static/img/fondo.jpg HTTP/1.1" 304 0
[10/Oct/2015 21:44:06] "GET /static/img/ribbon-2.png HTTP/1.1" 304 0
[10/Oct/2015 21:44:06] "GET /static/img/ribbon.png HTTP/1.1" 304 0
[10/Oct/2015 21:44:38] "GET /Login/ HTTP/1.1" 200 2122
[10/Oct/2015 21:44:38] "GET /static/css/base.css HTTP/1.1" 304 0
[10/Oct/2015 21:44:38] "GET /static/css/login.css HTTP/1.1" 304 0
[10/Oct/2015 21:44:38] "GET /static/css/bootstrap.min.css HTTP/1.1" 304 0
[10/Oct/2015 21:44:38] "GET /static/img/logo.png HTTP/1.1" 404 1649
[10/Oct/2015 21:44:38] "GET /static/js/bootstrap.min.js HTTP/1.1" 304 0
[10/Oct/2015 21:44:38] "GET /static/js/jquery-1.11.2.min.js HTTP/1.1" 304 0
[10/Oct/2015 21:44:38] "GET /static/img/header_corazon.gif HTTP/1.1" 304 0
[10/Oct/2015 21:44:38] "GET /static/img/fondo.jpg HTTP/1.1" 304 0
[10/Oct/2015 21:44:38] "GET /static/img/ribbon-2.png HTTP/1.1" 304 0
[10/Oct/2015 21:44:38] "GET /static/img/ribbon.png HTTP/1.1" 304 0
[10/Oct/2015 21:44:39] "GET /Login/ HTTP/1.1" 200 2122
[10/Oct/2015 21:44:39] "GET /static/css/bootstrap.min.css HTTP/1.1" 304 0
[10/Oct/2015 21:44:39] "GET /static/css/login.css HTTP/1.1" 304 0
[10/Oct/2015 21:44:39] "GET /static/css/base.css HTTP/1.1" 304 0
[10/Oct/2015 21:44:39] "GET /static/js/bootstrap.min.js HTTP/1.1" 304 0
[10/Oct/2015 21:44:39] "GET /static/js/jquery-1.11.2.min.js HTTP/1.1" 304 0
[10/Oct/2015 21:44:39] "GET /static/img/logo.png HTTP/1.1" 404 1649
[10/Oct/2015 21:44:39] "GET /static/img/header_corazon.gif HTTP/1.1" 304 0
[10/Oct/2015 21:44:39] "GET /static/img/fondo.jpg HTTP/1.1" 304 0
[10/Oct/2015 21:44:39] "GET /static/img/ribbon.png HTTP/1.1" 304 0
[10/Oct/2015 21:44:39] "GET /static/img/ribbon-2.png HTTP/1.1" 304 0
/home/joseagraz/Escritorio/pdvsa-t-d/pdvsa/urls.py:8: RemovedInDjango19Warning: Default value of 'RedirectView.permanent' will change from True to False in Django 1.9. Set an explicit value to silence this warning.
  url(r'^$', RedirectView.as_view(url=reverse_lazy('login'))),

[10/Oct/2015 22:46:26] "GET /Login/ HTTP/1.1" 200 2122
[10/Oct/2015 22:46:26] "GET /static/img/logo.png HTTP/1.1" 404 1649
[10/Oct/2015 22:46:41] "GET /Login/ HTTP/1.1" 200 2122
[10/Oct/2015 22:46:41] "GET /static/css/bootstrap.min.css HTTP/1.1" 304 0
[10/Oct/2015 22:46:41] "GET /static/css/login.css HTTP/1.1" 304 0
[10/Oct/2015 22:46:41] "GET /static/css/base.css HTTP/1.1" 304 0
[10/Oct/2015 22:46:41] "GET /static/js/jquery-1.11.2.min.js HTTP/1.1" 304 0
[10/Oct/2015 22:46:41] "GET /static/js/bootstrap.min.js HTTP/1.1" 304 0
[10/Oct/2015 22:46:41] "GET /static/img/header_corazon.gif HTTP/1.1" 304 0
[10/Oct/2015 22:46:41] "GET /static/img/logo.png HTTP/1.1" 404 1649
[10/Oct/2015 22:46:41] "GET /static/img/fondo.jpg HTTP/1.1" 304 0
[10/Oct/2015 22:46:41] "GET /static/img/ribbon.png HTTP/1.1" 304 0
[10/Oct/2015 22:46:41] "GET /static/img/ribbon-2.png HTTP/1.1" 304 0
[10/Oct/2015 22:46:51] "POST /Login/ HTTP/1.1" 302 0
[10/Oct/2015 22:46:51] "GET /Login HTTP/1.1" 301 0
[10/Oct/2015 22:46:51] "GET /Login/ HTTP/1.1" 200 2122
[10/Oct/2015 22:46:51] "GET /static/img/logo.png HTTP/1.1" 404 1649
[10/Oct/2015 22:47:04] "POST /Login/ HTTP/1.1" 302 0
[10/Oct/2015 22:47:04] "GET /Login HTTP/1.1" 301 0
[10/Oct/2015 22:47:04] "GET /Login/ HTTP/1.1" 200 2122
[10/Oct/2015 22:47:04] "GET /static/img/logo.png HTTP/1.1" 404 1649
[10/Oct/2015 22:47:11] "POST /Login/ HTTP/1.1" 302 0
[10/Oct/2015 22:47:11] "GET /control HTTP/1.1" 301 0
[10/Oct/2015 22:47:11] "GET /control/ HTTP/1.1" 200 7116
[10/Oct/2015 22:47:12] "GET /static/css/bootstrap-toggle.min.css HTTP/1.1" 200 1590
[10/Oct/2015 22:47:12] "GET /static/css/bootstrap-datetimepicker.css HTTP/1.1" 200 8860
[10/Oct/2015 22:47:12] "GET /static/css/bootstrapValidator.min.css HTTP/1.1" 200 565
[10/Oct/2015 22:47:12] "GET /static/css/dataTables.bootstrap.css HTTP/1.1" 200 8829
[10/Oct/2015 22:47:12] "GET /static/css/dashboard.css HTTP/1.1" 200 1453
[10/Oct/2015 22:47:12] "GET /static/js/dataTables.bootstrap.js HTTP/1.1" 200 4287
[10/Oct/2015 22:47:12] "GET /static/js/holder.js HTTP/1.1" 200 23861
[10/Oct/2015 22:47:12] "GET /static/js/jquery.dataTables.min.js HTTP/1.1" 200 79457
[10/Oct/2015 22:47:12] "GET /static/js/dataTables.tableTools.js HTTP/1.1" 200 84590
[10/Oct/2015 22:47:12] "GET /static/js/bootstrapValidator.min.js HTTP/1.1" 200 103316
[10/Oct/2015 22:47:12] "GET /static/js/base.js HTTP/1.1" 200 4238
[10/Oct/2015 22:47:12] "GET /static/js/bootstrap-datetimepicker.js HTTP/1.1" 200 79208
[10/Oct/2015 22:47:12] "GET /static/js/bootstrap-toggle.min.js HTTP/1.1" 200 4129
[10/Oct/2015 22:47:12] "GET /static/css/lib/select2/select2.css HTTP/1.1" 200 17062
[10/Oct/2015 22:47:12] "GET /static/js/moment.js HTTP/1.1" 200 348978
[10/Oct/2015 22:47:12] "GET /static/img/logo.png HTTP/1.1" 404 1649
[10/Oct/2015 22:47:12] "GET /static/js/lib/select2/select2.js HTTP/1.1" 200 132348
[10/Oct/2015 22:47:31] "GET /control/admin/registro/actividades/ HTTP/1.1" 200 8659
[10/Oct/2015 22:47:32] "GET /static/img/logo.png HTTP/1.1" 404 1649
[10/Oct/2015 22:47:36] "GET /logout/ HTTP/1.1" 302 0
[10/Oct/2015 22:47:36] "GET /Login/ HTTP/1.1" 200 2122
[10/Oct/2015 22:47:36] "GET /static/img/logo.png HTTP/1.1" 404 1649
[10/Oct/2015 22:47:44] "POST /Login/ HTTP/1.1" 302 0
[10/Oct/2015 22:47:44] "GET /control HTTP/1.1" 301 0
[10/Oct/2015 22:47:44] "GET /control/ HTTP/1.1" 200 7116
[10/Oct/2015 22:47:44] "GET /static/img/logo.png HTTP/1.1" 404 1649
[10/Oct/2015 22:48:02] "GET /logout/ HTTP/1.1" 302 0
[10/Oct/2015 22:48:02] "GET /Login/ HTTP/1.1" 200 2122
[10/Oct/2015 22:48:02] "GET /static/img/logo.png HTTP/1.1" 404 1649
[10/Oct/2015 22:49:25] "GET /Login/ HTTP/1.1" 200 2122
[10/Oct/2015 22:49:25] "GET /static/img/logo.png HTTP/1.1" 404 1649
Unhandled exception in thread started by <function wrapper at 0x7ff5496e6758>
Performing system checks...

Traceback (most recent call last):
  File "/home/joseagraz/Documentos/pdvsaenv/local/lib/python2.7/site-packages/django/utils/autoreload.py", line 229, in wrapper
    fn(*args, **kwargs)
  File "/home/joseagraz/Documentos/pdvsaenv/local/lib/python2.7/site-packages/django/core/management/commands/runserver.py", line 114, in inner_run
    self.validate(display_num_errors=True)
  File "/home/joseagraz/Documentos/pdvsaenv/local/lib/python2.7/site-packages/django/core/management/base.py", line 469, in validate
    return self.check(app_configs=app_configs, display_num_errors=display_num_errors)
  File "/home/joseagraz/Documentos/pdvsaenv/local/lib/python2.7/site-packages/django/core/management/base.py", line 482, in check
    include_deployment_checks=include_deployment_checks,
  File "/home/joseagraz/Documentos/pdvsaenv/local/lib/python2.7/site-packages/django/core/checks/registry.py", line 72, in run_checks
    new_errors = check(app_configs=app_configs)
  File "/home/joseagraz/Documentos/pdvsaenv/local/lib/python2.7/site-packages/django/core/checks/model_checks.py", line 28, in check_all_models
    errors.extend(model.check(**kwargs))
  File "/home/joseagraz/Documentos/pdvsaenv/local/lib/python2.7/site-packages/django/db/models/base.py", line 1205, in check
    errors.extend(cls._check_fields(**kwargs))
  File "/home/joseagraz/Documentos/pdvsaenv/local/lib/python2.7/site-packages/django/db/models/base.py", line 1282, in _check_fields
    errors.extend(field.check(**kwargs))
  File "/home/joseagraz/Documentos/pdvsaenv/local/lib/python2.7/site-packages/django/db/models/fields/__init__.py", line 934, in check
    errors = super(AutoField, self).check(**kwargs)
  File "/home/joseagraz/Documentos/pdvsaenv/local/lib/python2.7/site-packages/django/db/models/fields/__init__.py", line 207, in check
    errors.extend(self._check_backend_specific_checks(**kwargs))
  File "/home/joseagraz/Documentos/pdvsaenv/local/lib/python2.7/site-packages/django/db/models/fields/__init__.py", line 306, in _check_backend_specific_checks
    return connection.validation.check_field(self, **kwargs)
  File "/home/joseagraz/Documentos/pdvsaenv/local/lib/python2.7/site-packages/django/db/backends/mysql/validation.py", line 18, in check_field
    field_type = field.db_type(connection)
  File "/home/joseagraz/Documentos/pdvsaenv/local/lib/python2.7/site-packages/django/db/models/fields/__init__.py", line 614, in db_type
    return connection.data_types[self.get_internal_type()] % data
  File "/home/joseagraz/Documentos/pdvsaenv/local/lib/python2.7/site-packages/django/db/__init__.py", line 36, in __getattr__
    return getattr(connections[DEFAULT_DB_ALIAS], item)
  File "/home/joseagraz/Documentos/pdvsaenv/local/lib/python2.7/site-packages/django/utils/functional.py", line 59, in __get__
    res = instance.__dict__[self.name] = self.func(instance)
  File "/home/joseagraz/Documentos/pdvsaenv/local/lib/python2.7/site-packages/django/db/backends/mysql/base.py", line 196, in data_types
    if self.features.supports_microsecond_precision:
  File "/home/joseagraz/Documentos/pdvsaenv/local/lib/python2.7/site-packages/django/utils/functional.py", line 59, in __get__
    res = instance.__dict__[self.name] = self.func(instance)
  File "/home/joseagraz/Documentos/pdvsaenv/local/lib/python2.7/site-packages/django/db/backends/mysql/features.py", line 52, in supports_microsecond_precision
    return self.connection.mysql_version >= (5, 6, 4) and Database.version_info >= (1, 2, 5)
  File "/home/joseagraz/Documentos/pdvsaenv/local/lib/python2.7/site-packages/django/utils/functional.py", line 59, in __get__
    res = instance.__dict__[self.name] = self.func(instance)
  File "/home/joseagraz/Documentos/pdvsaenv/local/lib/python2.7/site-packages/django/db/backends/mysql/base.py", line 371, in mysql_version
    with self.temporary_connection():
  File "/usr/lib/python2.7/contextlib.py", line 17, in __enter__
    return self.gen.next()
  File "/home/joseagraz/Documentos/pdvsaenv/local/lib/python2.7/site-packages/django/db/backends/base/base.py", line 462, in temporary_connection
    cursor = self.cursor()
  File "/home/joseagraz/Documentos/pdvsaenv/local/lib/python2.7/site-packages/django/db/backends/base/base.py", line 162, in cursor
    cursor = self.make_debug_cursor(self._cursor())
  File "/home/joseagraz/Documentos/pdvsaenv/local/lib/python2.7/site-packages/django/db/backends/base/base.py", line 135, in _cursor
    self.ensure_connection()
  File "/home/joseagraz/Documentos/pdvsaenv/local/lib/python2.7/site-packages/django/db/backends/base/base.py", line 130, in ensure_connection
    self.connect()
  File "/home/joseagraz/Documentos/pdvsaenv/local/lib/python2.7/site-packages/django/db/utils.py", line 97, in __exit__
    six.reraise(dj_exc_type, dj_exc_value, traceback)
  File "/home/joseagraz/Documentos/pdvsaenv/local/lib/python2.7/site-packages/django/db/backends/base/base.py", line 130, in ensure_connection
    self.connect()
  File "/home/joseagraz/Documentos/pdvsaenv/local/lib/python2.7/site-packages/django/db/backends/base/base.py", line 119, in connect
    self.connection = self.get_new_connection(conn_params)
  File "/home/joseagraz/Documentos/pdvsaenv/local/lib/python2.7/site-packages/django/db/backends/mysql/base.py", line 276, in get_new_connection
    conn = Database.connect(**conn_params)
  File "/home/joseagraz/Documentos/pdvsaenv/local/lib/python2.7/site-packages/MySQLdb/__init__.py", line 81, in Connect
    return Connection(*args, **kwargs)
  File "/home/joseagraz/Documentos/pdvsaenv/local/lib/python2.7/site-packages/MySQLdb/connections.py", line 193, in __init__
    super(Connection, self).__init__(*args, **kwargs2)
django.db.utils.OperationalError: (2003, "Can't connect to MySQL server on '127.0.0.1' (111)")
Unhandled exception in thread started by <function wrapper at 0x7f851b5b0758>
Performing system checks...

Traceback (most recent call last):
  File "/home/joseagraz/Documentos/pdvsaenv/local/lib/python2.7/site-packages/django/utils/autoreload.py", line 229, in wrapper
    fn(*args, **kwargs)
  File "/home/joseagraz/Documentos/pdvsaenv/local/lib/python2.7/site-packages/django/core/management/commands/runserver.py", line 114, in inner_run
    self.validate(display_num_errors=True)
  File "/home/joseagraz/Documentos/pdvsaenv/local/lib/python2.7/site-packages/django/core/management/base.py", line 469, in validate
    return self.check(app_configs=app_configs, display_num_errors=display_num_errors)
  File "/home/joseagraz/Documentos/pdvsaenv/local/lib/python2.7/site-packages/django/core/management/base.py", line 482, in check
    include_deployment_checks=include_deployment_checks,
  File "/home/joseagraz/Documentos/pdvsaenv/local/lib/python2.7/site-packages/django/core/checks/registry.py", line 72, in run_checks
    new_errors = check(app_configs=app_configs)
  File "/home/joseagraz/Documentos/pdvsaenv/local/lib/python2.7/site-packages/django/core/checks/model_checks.py", line 28, in check_all_models
    errors.extend(model.check(**kwargs))
  File "/home/joseagraz/Documentos/pdvsaenv/local/lib/python2.7/site-packages/django/db/models/base.py", line 1205, in check
    errors.extend(cls._check_fields(**kwargs))
  File "/home/joseagraz/Documentos/pdvsaenv/local/lib/python2.7/site-packages/django/db/models/base.py", line 1282, in _check_fields
    errors.extend(field.check(**kwargs))
  File "/home/joseagraz/Documentos/pdvsaenv/local/lib/python2.7/site-packages/django/db/models/fields/__init__.py", line 934, in check
    errors = super(AutoField, self).check(**kwargs)
  File "/home/joseagraz/Documentos/pdvsaenv/local/lib/python2.7/site-packages/django/db/models/fields/__init__.py", line 207, in check
    errors.extend(self._check_backend_specific_checks(**kwargs))
  File "/home/joseagraz/Documentos/pdvsaenv/local/lib/python2.7/site-packages/django/db/models/fields/__init__.py", line 306, in _check_backend_specific_checks
    return connection.validation.check_field(self, **kwargs)
  File "/home/joseagraz/Documentos/pdvsaenv/local/lib/python2.7/site-packages/django/db/backends/mysql/validation.py", line 18, in check_field
    field_type = field.db_type(connection)
  File "/home/joseagraz/Documentos/pdvsaenv/local/lib/python2.7/site-packages/django/db/models/fields/__init__.py", line 614, in db_type
    return connection.data_types[self.get_internal_type()] % data
  File "/home/joseagraz/Documentos/pdvsaenv/local/lib/python2.7/site-packages/django/db/__init__.py", line 36, in __getattr__
    return getattr(connections[DEFAULT_DB_ALIAS], item)
  File "/home/joseagraz/Documentos/pdvsaenv/local/lib/python2.7/site-packages/django/utils/functional.py", line 59, in __get__
    res = instance.__dict__[self.name] = self.func(instance)
  File "/home/joseagraz/Documentos/pdvsaenv/local/lib/python2.7/site-packages/django/db/backends/mysql/base.py", line 196, in data_types
    if self.features.supports_microsecond_precision:
  File "/home/joseagraz/Documentos/pdvsaenv/local/lib/python2.7/site-packages/django/utils/functional.py", line 59, in __get__
    res = instance.__dict__[self.name] = self.func(instance)
  File "/home/joseagraz/Documentos/pdvsaenv/local/lib/python2.7/site-packages/django/db/backends/mysql/features.py", line 52, in supports_microsecond_precision
    return self.connection.mysql_version >= (5, 6, 4) and Database.version_info >= (1, 2, 5)
  File "/home/joseagraz/Documentos/pdvsaenv/local/lib/python2.7/site-packages/django/utils/functional.py", line 59, in __get__
    res = instance.__dict__[self.name] = self.func(instance)
  File "/home/joseagraz/Documentos/pdvsaenv/local/lib/python2.7/site-packages/django/db/backends/mysql/base.py", line 371, in mysql_version
    with self.temporary_connection():
  File "/usr/lib/python2.7/contextlib.py", line 17, in __enter__
    return self.gen.next()
  File "/home/joseagraz/Documentos/pdvsaenv/local/lib/python2.7/site-packages/django/db/backends/base/base.py", line 462, in temporary_connection
    cursor = self.cursor()
  File "/home/joseagraz/Documentos/pdvsaenv/local/lib/python2.7/site-packages/django/db/backends/base/base.py", line 162, in cursor
    cursor = self.make_debug_cursor(self._cursor())
  File "/home/joseagraz/Documentos/pdvsaenv/local/lib/python2.7/site-packages/django/db/backends/base/base.py", line 135, in _cursor
    self.ensure_connection()
  File "/home/joseagraz/Documentos/pdvsaenv/local/lib/python2.7/site-packages/django/db/backends/base/base.py", line 130, in ensure_connection
    self.connect()
  File "/home/joseagraz/Documentos/pdvsaenv/local/lib/python2.7/site-packages/django/db/utils.py", line 97, in __exit__
    six.reraise(dj_exc_type, dj_exc_value, traceback)
  File "/home/joseagraz/Documentos/pdvsaenv/local/lib/python2.7/site-packages/django/db/backends/base/base.py", line 130, in ensure_connection
    self.connect()
  File "/home/joseagraz/Documentos/pdvsaenv/local/lib/python2.7/site-packages/django/db/backends/base/base.py", line 119, in connect
    self.connection = self.get_new_connection(conn_params)
  File "/home/joseagraz/Documentos/pdvsaenv/local/lib/python2.7/site-packages/django/db/backends/mysql/base.py", line 276, in get_new_connection
    conn = Database.connect(**conn_params)
  File "/home/joseagraz/Documentos/pdvsaenv/local/lib/python2.7/site-packages/MySQLdb/__init__.py", line 81, in Connect
    return Connection(*args, **kwargs)
  File "/home/joseagraz/Documentos/pdvsaenv/local/lib/python2.7/site-packages/MySQLdb/connections.py", line 193, in __init__
    super(Connection, self).__init__(*args, **kwargs2)
django.db.utils.OperationalError: (2003, "Can't connect to MySQL server on '127.0.0.1' (111)")
Unhandled exception in thread started by <function wrapper at 0x7f91277e3758>
Performing system checks...

Traceback (most recent call last):
  File "/home/joseagraz/Documentos/pdvsaenv/local/lib/python2.7/site-packages/django/utils/autoreload.py", line 229, in wrapper
    fn(*args, **kwargs)
  File "/home/joseagraz/Documentos/pdvsaenv/local/lib/python2.7/site-packages/django/core/management/commands/runserver.py", line 114, in inner_run
    self.validate(display_num_errors=True)
  File "/home/joseagraz/Documentos/pdvsaenv/local/lib/python2.7/site-packages/django/core/management/base.py", line 469, in validate
    return self.check(app_configs=app_configs, display_num_errors=display_num_errors)
  File "/home/joseagraz/Documentos/pdvsaenv/local/lib/python2.7/site-packages/django/core/management/base.py", line 482, in check
    include_deployment_checks=include_deployment_checks,
  File "/home/joseagraz/Documentos/pdvsaenv/local/lib/python2.7/site-packages/django/core/checks/registry.py", line 72, in run_checks
    new_errors = check(app_configs=app_configs)
  File "/home/joseagraz/Documentos/pdvsaenv/local/lib/python2.7/site-packages/django/core/checks/model_checks.py", line 28, in check_all_models
    errors.extend(model.check(**kwargs))
  File "/home/joseagraz/Documentos/pdvsaenv/local/lib/python2.7/site-packages/django/db/models/base.py", line 1205, in check
    errors.extend(cls._check_fields(**kwargs))
  File "/home/joseagraz/Documentos/pdvsaenv/local/lib/python2.7/site-packages/django/db/models/base.py", line 1282, in _check_fields
    errors.extend(field.check(**kwargs))
  File "/home/joseagraz/Documentos/pdvsaenv/local/lib/python2.7/site-packages/django/db/models/fields/__init__.py", line 934, in check
    errors = super(AutoField, self).check(**kwargs)
  File "/home/joseagraz/Documentos/pdvsaenv/local/lib/python2.7/site-packages/django/db/models/fields/__init__.py", line 207, in check
    errors.extend(self._check_backend_specific_checks(**kwargs))
  File "/home/joseagraz/Documentos/pdvsaenv/local/lib/python2.7/site-packages/django/db/models/fields/__init__.py", line 306, in _check_backend_specific_checks
    return connection.validation.check_field(self, **kwargs)
  File "/home/joseagraz/Documentos/pdvsaenv/local/lib/python2.7/site-packages/django/db/backends/mysql/validation.py", line 18, in check_field
    field_type = field.db_type(connection)
  File "/home/joseagraz/Documentos/pdvsaenv/local/lib/python2.7/site-packages/django/db/models/fields/__init__.py", line 614, in db_type
    return connection.data_types[self.get_internal_type()] % data
  File "/home/joseagraz/Documentos/pdvsaenv/local/lib/python2.7/site-packages/django/db/__init__.py", line 36, in __getattr__
    return getattr(connections[DEFAULT_DB_ALIAS], item)
  File "/home/joseagraz/Documentos/pdvsaenv/local/lib/python2.7/site-packages/django/utils/functional.py", line 59, in __get__
    res = instance.__dict__[self.name] = self.func(instance)
  File "/home/joseagraz/Documentos/pdvsaenv/local/lib/python2.7/site-packages/django/db/backends/mysql/base.py", line 196, in data_types
    if self.features.supports_microsecond_precision:
  File "/home/joseagraz/Documentos/pdvsaenv/local/lib/python2.7/site-packages/django/utils/functional.py", line 59, in __get__
    res = instance.__dict__[self.name] = self.func(instance)
  File "/home/joseagraz/Documentos/pdvsaenv/local/lib/python2.7/site-packages/django/db/backends/mysql/features.py", line 52, in supports_microsecond_precision
    return self.connection.mysql_version >= (5, 6, 4) and Database.version_info >= (1, 2, 5)
  File "/home/joseagraz/Documentos/pdvsaenv/local/lib/python2.7/site-packages/django/utils/functional.py", line 59, in __get__
    res = instance.__dict__[self.name] = self.func(instance)
  File "/home/joseagraz/Documentos/pdvsaenv/local/lib/python2.7/site-packages/django/db/backends/mysql/base.py", line 371, in mysql_version
    with self.temporary_connection():
  File "/usr/lib/python2.7/contextlib.py", line 17, in __enter__
    return self.gen.next()
  File "/home/joseagraz/Documentos/pdvsaenv/local/lib/python2.7/site-packages/django/db/backends/base/base.py", line 462, in temporary_connection
    cursor = self.cursor()
  File "/home/joseagraz/Documentos/pdvsaenv/local/lib/python2.7/site-packages/django/db/backends/base/base.py", line 162, in cursor
    cursor = self.make_debug_cursor(self._cursor())
  File "/home/joseagraz/Documentos/pdvsaenv/local/lib/python2.7/site-packages/django/db/backends/base/base.py", line 135, in _cursor
    self.ensure_connection()
  File "/home/joseagraz/Documentos/pdvsaenv/local/lib/python2.7/site-packages/django/db/backends/base/base.py", line 130, in ensure_connection
    self.connect()
  File "/home/joseagraz/Documentos/pdvsaenv/local/lib/python2.7/site-packages/django/db/utils.py", line 97, in __exit__
    six.reraise(dj_exc_type, dj_exc_value, traceback)
  File "/home/joseagraz/Documentos/pdvsaenv/local/lib/python2.7/site-packages/django/db/backends/base/base.py", line 130, in ensure_connection
    self.connect()
  File "/home/joseagraz/Documentos/pdvsaenv/local/lib/python2.7/site-packages/django/db/backends/base/base.py", line 119, in connect
    self.connection = self.get_new_connection(conn_params)
  File "/home/joseagraz/Documentos/pdvsaenv/local/lib/python2.7/site-packages/django/db/backends/mysql/base.py", line 276, in get_new_connection
    conn = Database.connect(**conn_params)
  File "/home/joseagraz/Documentos/pdvsaenv/local/lib/python2.7/site-packages/MySQLdb/__init__.py", line 81, in Connect
    return Connection(*args, **kwargs)
  File "/home/joseagraz/Documentos/pdvsaenv/local/lib/python2.7/site-packages/MySQLdb/connections.py", line 193, in __init__
    super(Connection, self).__init__(*args, **kwargs2)
django.db.utils.OperationalError: (2003, "Can't connect to MySQL server on '127.0.0.1' (111)")
Unhandled exception in thread started by <function wrapper at 0x7f26892f1758>
Performing system checks...

Traceback (most recent call last):
  File "/home/joseagraz/Documentos/pdvsaenv/local/lib/python2.7/site-packages/django/utils/autoreload.py", line 229, in wrapper
    fn(*args, **kwargs)
  File "/home/joseagraz/Documentos/pdvsaenv/local/lib/python2.7/site-packages/django/core/management/commands/runserver.py", line 114, in inner_run
    self.validate(display_num_errors=True)
  File "/home/joseagraz/Documentos/pdvsaenv/local/lib/python2.7/site-packages/django/core/management/base.py", line 469, in validate
    return self.check(app_configs=app_configs, display_num_errors=display_num_errors)
  File "/home/joseagraz/Documentos/pdvsaenv/local/lib/python2.7/site-packages/django/core/management/base.py", line 482, in check
    include_deployment_checks=include_deployment_checks,
  File "/home/joseagraz/Documentos/pdvsaenv/local/lib/python2.7/site-packages/django/core/checks/registry.py", line 72, in run_checks
    new_errors = check(app_configs=app_configs)
  File "/home/joseagraz/Documentos/pdvsaenv/local/lib/python2.7/site-packages/django/core/checks/model_checks.py", line 28, in check_all_models
    errors.extend(model.check(**kwargs))
  File "/home/joseagraz/Documentos/pdvsaenv/local/lib/python2.7/site-packages/django/db/models/base.py", line 1205, in check
    errors.extend(cls._check_fields(**kwargs))
  File "/home/joseagraz/Documentos/pdvsaenv/local/lib/python2.7/site-packages/django/db/models/base.py", line 1282, in _check_fields
    errors.extend(field.check(**kwargs))
  File "/home/joseagraz/Documentos/pdvsaenv/local/lib/python2.7/site-packages/django/db/models/fields/__init__.py", line 934, in check
    errors = super(AutoField, self).check(**kwargs)
  File "/home/joseagraz/Documentos/pdvsaenv/local/lib/python2.7/site-packages/django/db/models/fields/__init__.py", line 207, in check
    errors.extend(self._check_backend_specific_checks(**kwargs))
  File "/home/joseagraz/Documentos/pdvsaenv/local/lib/python2.7/site-packages/django/db/models/fields/__init__.py", line 306, in _check_backend_specific_checks
    return connection.validation.check_field(self, **kwargs)
  File "/home/joseagraz/Documentos/pdvsaenv/local/lib/python2.7/site-packages/django/db/backends/mysql/validation.py", line 18, in check_field
    field_type = field.db_type(connection)
  File "/home/joseagraz/Documentos/pdvsaenv/local/lib/python2.7/site-packages/django/db/models/fields/__init__.py", line 614, in db_type
    return connection.data_types[self.get_internal_type()] % data
  File "/home/joseagraz/Documentos/pdvsaenv/local/lib/python2.7/site-packages/django/db/__init__.py", line 36, in __getattr__
    return getattr(connections[DEFAULT_DB_ALIAS], item)
  File "/home/joseagraz/Documentos/pdvsaenv/local/lib/python2.7/site-packages/django/utils/functional.py", line 59, in __get__
    res = instance.__dict__[self.name] = self.func(instance)
  File "/home/joseagraz/Documentos/pdvsaenv/local/lib/python2.7/site-packages/django/db/backends/mysql/base.py", line 196, in data_types
    if self.features.supports_microsecond_precision:
  File "/home/joseagraz/Documentos/pdvsaenv/local/lib/python2.7/site-packages/django/utils/functional.py", line 59, in __get__
    res = instance.__dict__[self.name] = self.func(instance)
  File "/home/joseagraz/Documentos/pdvsaenv/local/lib/python2.7/site-packages/django/db/backends/mysql/features.py", line 52, in supports_microsecond_precision
    return self.connection.mysql_version >= (5, 6, 4) and Database.version_info >= (1, 2, 5)
  File "/home/joseagraz/Documentos/pdvsaenv/local/lib/python2.7/site-packages/django/utils/functional.py", line 59, in __get__
    res = instance.__dict__[self.name] = self.func(instance)
  File "/home/joseagraz/Documentos/pdvsaenv/local/lib/python2.7/site-packages/django/db/backends/mysql/base.py", line 371, in mysql_version
    with self.temporary_connection():
  File "/usr/lib/python2.7/contextlib.py", line 17, in __enter__
    return self.gen.next()
  File "/home/joseagraz/Documentos/pdvsaenv/local/lib/python2.7/site-packages/django/db/backends/base/base.py", line 462, in temporary_connection
    cursor = self.cursor()
  File "/home/joseagraz/Documentos/pdvsaenv/local/lib/python2.7/site-packages/django/db/backends/base/base.py", line 162, in cursor
    cursor = self.make_debug_cursor(self._cursor())
  File "/home/joseagraz/Documentos/pdvsaenv/local/lib/python2.7/site-packages/django/db/backends/base/base.py", line 135, in _cursor
    self.ensure_connection()
  File "/home/joseagraz/Documentos/pdvsaenv/local/lib/python2.7/site-packages/django/db/backends/base/base.py", line 130, in ensure_connection
    self.connect()
  File "/home/joseagraz/Documentos/pdvsaenv/local/lib/python2.7/site-packages/django/db/utils.py", line 97, in __exit__
    six.reraise(dj_exc_type, dj_exc_value, traceback)
  File "/home/joseagraz/Documentos/pdvsaenv/local/lib/python2.7/site-packages/django/db/backends/base/base.py", line 130, in ensure_connection
    self.connect()
  File "/home/joseagraz/Documentos/pdvsaenv/local/lib/python2.7/site-packages/django/db/backends/base/base.py", line 119, in connect
    self.connection = self.get_new_connection(conn_params)
  File "/home/joseagraz/Documentos/pdvsaenv/local/lib/python2.7/site-packages/django/db/backends/mysql/base.py", line 276, in get_new_connection
    conn = Database.connect(**conn_params)
  File "/home/joseagraz/Documentos/pdvsaenv/local/lib/python2.7/site-packages/MySQLdb/__init__.py", line 81, in Connect
    return Connection(*args, **kwargs)
  File "/home/joseagraz/Documentos/pdvsaenv/local/lib/python2.7/site-packages/MySQLdb/connections.py", line 193, in __init__
    super(Connection, self).__init__(*args, **kwargs2)
django.db.utils.OperationalError: (2003, "Can't connect to MySQL server on '127.0.0.1' (111)")
Unhandled exception in thread started by <function wrapper at 0x7f1c87c05758>
Performing system checks...

Traceback (most recent call last):
  File "/home/joseagraz/Documentos/pdvsaenv/local/lib/python2.7/site-packages/django/utils/autoreload.py", line 229, in wrapper
    fn(*args, **kwargs)
  File "/home/joseagraz/Documentos/pdvsaenv/local/lib/python2.7/site-packages/django/core/management/commands/runserver.py", line 114, in inner_run
    self.validate(display_num_errors=True)
  File "/home/joseagraz/Documentos/pdvsaenv/local/lib/python2.7/site-packages/django/core/management/base.py", line 469, in validate
    return self.check(app_configs=app_configs, display_num_errors=display_num_errors)
  File "/home/joseagraz/Documentos/pdvsaenv/local/lib/python2.7/site-packages/django/core/management/base.py", line 482, in check
    include_deployment_checks=include_deployment_checks,
  File "/home/joseagraz/Documentos/pdvsaenv/local/lib/python2.7/site-packages/django/core/checks/registry.py", line 72, in run_checks
    new_errors = check(app_configs=app_configs)
  File "/home/joseagraz/Documentos/pdvsaenv/local/lib/python2.7/site-packages/django/core/checks/model_checks.py", line 28, in check_all_models
    errors.extend(model.check(**kwargs))
  File "/home/joseagraz/Documentos/pdvsaenv/local/lib/python2.7/site-packages/django/db/models/base.py", line 1205, in check
    errors.extend(cls._check_fields(**kwargs))
  File "/home/joseagraz/Documentos/pdvsaenv/local/lib/python2.7/site-packages/django/db/models/base.py", line 1282, in _check_fields
    errors.extend(field.check(**kwargs))
  File "/home/joseagraz/Documentos/pdvsaenv/local/lib/python2.7/site-packages/django/db/models/fields/__init__.py", line 934, in check
    errors = super(AutoField, self).check(**kwargs)
  File "/home/joseagraz/Documentos/pdvsaenv/local/lib/python2.7/site-packages/django/db/models/fields/__init__.py", line 207, in check
    errors.extend(self._check_backend_specific_checks(**kwargs))
  File "/home/joseagraz/Documentos/pdvsaenv/local/lib/python2.7/site-packages/django/db/models/fields/__init__.py", line 306, in _check_backend_specific_checks
    return connection.validation.check_field(self, **kwargs)
  File "/home/joseagraz/Documentos/pdvsaenv/local/lib/python2.7/site-packages/django/db/backends/mysql/validation.py", line 18, in check_field
    field_type = field.db_type(connection)
  File "/home/joseagraz/Documentos/pdvsaenv/local/lib/python2.7/site-packages/django/db/models/fields/__init__.py", line 614, in db_type
    return connection.data_types[self.get_internal_type()] % data
  File "/home/joseagraz/Documentos/pdvsaenv/local/lib/python2.7/site-packages/django/db/__init__.py", line 36, in __getattr__
    return getattr(connections[DEFAULT_DB_ALIAS], item)
  File "/home/joseagraz/Documentos/pdvsaenv/local/lib/python2.7/site-packages/django/utils/functional.py", line 59, in __get__
    res = instance.__dict__[self.name] = self.func(instance)
  File "/home/joseagraz/Documentos/pdvsaenv/local/lib/python2.7/site-packages/django/db/backends/mysql/base.py", line 196, in data_types
    if self.features.supports_microsecond_precision:
  File "/home/joseagraz/Documentos/pdvsaenv/local/lib/python2.7/site-packages/django/utils/functional.py", line 59, in __get__
    res = instance.__dict__[self.name] = self.func(instance)
  File "/home/joseagraz/Documentos/pdvsaenv/local/lib/python2.7/site-packages/django/db/backends/mysql/features.py", line 52, in supports_microsecond_precision
    return self.connection.mysql_version >= (5, 6, 4) and Database.version_info >= (1, 2, 5)
  File "/home/joseagraz/Documentos/pdvsaenv/local/lib/python2.7/site-packages/django/utils/functional.py", line 59, in __get__
    res = instance.__dict__[self.name] = self.func(instance)
  File "/home/joseagraz/Documentos/pdvsaenv/local/lib/python2.7/site-packages/django/db/backends/mysql/base.py", line 371, in mysql_version
    with self.temporary_connection():
  File "/usr/lib/python2.7/contextlib.py", line 17, in __enter__
    return self.gen.next()
  File "/home/joseagraz/Documentos/pdvsaenv/local/lib/python2.7/site-packages/django/db/backends/base/base.py", line 462, in temporary_connection
    cursor = self.cursor()
  File "/home/joseagraz/Documentos/pdvsaenv/local/lib/python2.7/site-packages/django/db/backends/base/base.py", line 162, in cursor
    cursor = self.make_debug_cursor(self._cursor())
  File "/home/joseagraz/Documentos/pdvsaenv/local/lib/python2.7/site-packages/django/db/backends/base/base.py", line 135, in _cursor
    self.ensure_connection()
  File "/home/joseagraz/Documentos/pdvsaenv/local/lib/python2.7/site-packages/django/db/backends/base/base.py", line 130, in ensure_connection
    self.connect()
  File "/home/joseagraz/Documentos/pdvsaenv/local/lib/python2.7/site-packages/django/db/utils.py", line 97, in __exit__
    six.reraise(dj_exc_type, dj_exc_value, traceback)
  File "/home/joseagraz/Documentos/pdvsaenv/local/lib/python2.7/site-packages/django/db/backends/base/base.py", line 130, in ensure_connection
    self.connect()
  File "/home/joseagraz/Documentos/pdvsaenv/local/lib/python2.7/site-packages/django/db/backends/base/base.py", line 119, in connect
    self.connection = self.get_new_connection(conn_params)
  File "/home/joseagraz/Documentos/pdvsaenv/local/lib/python2.7/site-packages/django/db/backends/mysql/base.py", line 276, in get_new_connection
    conn = Database.connect(**conn_params)
  File "/home/joseagraz/Documentos/pdvsaenv/local/lib/python2.7/site-packages/MySQLdb/__init__.py", line 81, in Connect
    return Connection(*args, **kwargs)
  File "/home/joseagraz/Documentos/pdvsaenv/local/lib/python2.7/site-packages/MySQLdb/connections.py", line 193, in __init__
    super(Connection, self).__init__(*args, **kwargs2)
django.db.utils.OperationalError: (2003, "Can't connect to MySQL server on '127.0.0.1' (111)")
/home/joseagraz/Documentos/pdvsa-t-d/pdvsa/urls.py:8: RemovedInDjango19Warning: Default value of 'RedirectView.permanent' will change from True to False in Django 1.9. Set an explicit value to silence this warning.
  url(r'^$', RedirectView.as_view(url=reverse_lazy('login'))),

[13/Oct/2015 21:27:30] "GET /Login/ HTTP/1.1" 200 2122
[13/Oct/2015 21:27:30] "GET /static/img/logo.png HTTP/1.1" 404 1649
[13/Oct/2015 21:27:31] "GET /static/css/base.css HTTP/1.1" 304 0
[13/Oct/2015 21:27:41] "POST /Login/ HTTP/1.1" 500 161428
[13/Oct/2015 21:27:41] "GET /favicon.ico HTTP/1.1" 404 2392
[13/Oct/2015 21:27:41] "GET /favicon.ico HTTP/1.1" 404 2392
[13/Oct/2015 21:29:28] "POST /Login/ HTTP/1.1" 500 161396
[13/Oct/2015 21:29:39] "POST /Login/ HTTP/1.1" 500 161397
/home/joseagraz/Documentos/pdvsa-t-d/pdvsa/urls.py:8: RemovedInDjango19Warning: Default value of 'RedirectView.permanent' will change from True to False in Django 1.9. Set an explicit value to silence this warning.
  url(r'^$', RedirectView.as_view(url=reverse_lazy('login'))),

[22/Oct/2015 16:56:17] "GET /Login/ HTTP/1.1" 200 2122
[22/Oct/2015 16:56:18] "GET /static/img/logo.png HTTP/1.1" 404 1649
[22/Oct/2015 16:56:18] "GET /static/css/base.css HTTP/1.1" 304 0
[22/Oct/2015 16:56:24] "POST /Login/ HTTP/1.1" 302 0
[22/Oct/2015 16:56:24] "GET /control HTTP/1.1" 301 0
[22/Oct/2015 16:56:25] "GET /control/ HTTP/1.1" 200 7340
[22/Oct/2015 16:56:25] "GET /static/img/logo.png HTTP/1.1" 404 1649
[22/Oct/2015 16:56:25] "GET /static/img/chavez1.jpeg HTTP/1.1" 200 22283
[22/Oct/2015 16:56:25] "GET /static/js/base.js HTTP/1.1" 304 0
[22/Oct/2015 16:57:03] "GET /control/admin/registro/actividades/ HTTP/1.1" 200 8729
[22/Oct/2015 16:57:03] "GET /static/img/logo.png HTTP/1.1" 404 1649
[22/Oct/2015 16:57:08] "GET /control/admin/registro/procesos/ HTTP/1.1" 200 8511
[22/Oct/2015 16:57:08] "GET /static/img/logo.png HTTP/1.1" 404 1649
[22/Oct/2015 16:57:14] "GET /logout/ HTTP/1.1" 302 0
[22/Oct/2015 16:57:14] "GET /Login/ HTTP/1.1" 200 2122
[22/Oct/2015 16:57:14] "GET /static/img/logo.png HTTP/1.1" 404 1649
[22/Oct/2015 16:59:10] "GET /Login/ HTTP/1.1" 200 2122
[22/Oct/2015 16:59:10] "GET /static/img/logo.png HTTP/1.1" 404 1649
[22/Oct/2015 16:59:21] "GET /admin/ HTTP/1.1" 302 0
[22/Oct/2015 16:59:21] "GET /admin/login/?next=/admin/ HTTP/1.1" 200 1963
[22/Oct/2015 16:59:21] "GET /static/admin/css/base.css HTTP/1.1" 200 14049
[22/Oct/2015 16:59:21] "GET /static/admin/css/login.css HTTP/1.1" 200 940
[22/Oct/2015 16:59:21] "GET /static/admin/img/nav-bg.gif HTTP/1.1" 200 265
[22/Oct/2015 16:59:21] "GET /favicon.ico HTTP/1.1" 404 2392
[22/Oct/2015 16:59:24] "GET /static/admin/img/nav-bg-reverse.gif HTTP/1.1" 200 178
[22/Oct/2015 16:59:24] "POST /admin/login/?next=/admin/ HTTP/1.1" 302 0
[22/Oct/2015 16:59:24] "GET /admin/ HTTP/1.1" 200 6118
[22/Oct/2015 16:59:24] "GET /static/admin/css/dashboard.css HTTP/1.1" 200 434
[22/Oct/2015 16:59:24] "GET /static/admin/img/default-bg.gif HTTP/1.1" 200 836
[22/Oct/2015 16:59:24] "GET /static/admin/img/icon_addlink.gif HTTP/1.1" 200 119
[22/Oct/2015 16:59:24] "GET /static/admin/img/icon_changelink.gif HTTP/1.1" 200 119
[22/Oct/2015 16:59:30] "GET /admin/auth/user/ HTTP/1.1" 200 6728
[22/Oct/2015 16:59:30] "GET /static/admin/js/core.js HTTP/1.1" 200 7522
[22/Oct/2015 16:59:30] "GET /static/admin/css/changelists.css HTTP/1.1" 200 5254
[22/Oct/2015 16:59:30] "GET /static/admin/js/admin/RelatedObjectLookups.js HTTP/1.1" 200 4464
[22/Oct/2015 16:59:30] "GET /static/admin/js/jquery.js HTTP/1.1" 200 284184
[22/Oct/2015 16:59:30] "GET /static/admin/js/jquery.init.js HTTP/1.1" 200 326
[22/Oct/2015 16:59:30] "GET /static/admin/js/actions.js HTTP/1.1" 200 4910
[22/Oct/2015 16:59:30] "GET /admin/jsi18n/ HTTP/1.1" 200 6408
[22/Oct/2015 16:59:30] "GET /static/admin/img/icon_searchbox.png HTTP/1.1" 200 368
[22/Oct/2015 16:59:30] "GET /static/admin/img/icon-yes.gif HTTP/1.1" 200 299
[22/Oct/2015 16:59:30] "GET /static/admin/img/tooltag-add.png HTTP/1.1" 200 119
[22/Oct/2015 16:59:30] "GET /static/admin/img/changelist-bg.gif HTTP/1.1" 200 50
[22/Oct/2015 16:59:30] "GET /static/admin/img/nav-bg-selected.gif HTTP/1.1" 200 265
[22/Oct/2015 16:59:30] "GET /static/admin/img/sorting-icons.gif HTTP/1.1" 200 369
[22/Oct/2015 16:59:41] "GET /admin/core/persona/ HTTP/1.1" 200 3207
[22/Oct/2015 16:59:41] "GET /admin/jsi18n/ HTTP/1.1" 200 6408
[22/Oct/2015 16:59:44] "GET /admin/core/persona/add/ HTTP/1.1" 200 5466
[22/Oct/2015 16:59:44] "GET /static/admin/css/forms.css HTTP/1.1" 200 6283
[22/Oct/2015 16:59:44] "GET /static/admin/css/widgets.css HTTP/1.1" 200 10590
[22/Oct/2015 16:59:44] "GET /static/admin/js/related-widget-wrapper.js HTTP/1.1" 200 857
[22/Oct/2015 16:59:44] "GET /admin/jsi18n/ HTTP/1.1" 200 6408
[22/Oct/2015 17:00:01] "GET /admin/auth/user/add/?_to_field=id&_popup=1 HTTP/1.1" 200 4495
[22/Oct/2015 17:00:01] "GET /admin/jsi18n/ HTTP/1.1" 200 6408
[22/Oct/2015 17:00:19] "GET /admin/auth/user/ HTTP/1.1" 200 6728
[22/Oct/2015 17:00:19] "GET /admin/jsi18n/ HTTP/1.1" 200 6408
[22/Oct/2015 17:00:32] "GET /admin/auth/user/add/ HTTP/1.1" 200 5573
[22/Oct/2015 17:00:32] "GET /admin/jsi18n/ HTTP/1.1" 200 6408
[22/Oct/2015 17:00:51] "POST /admin/auth/user/add/ HTTP/1.1" 200 5769
[22/Oct/2015 17:00:51] "GET /admin/jsi18n/ HTTP/1.1" 200 6408
[22/Oct/2015 17:00:51] "GET /static/admin/img/icon_error.gif HTTP/1.1" 200 319
[22/Oct/2015 17:01:07] "POST /admin/auth/user/add/ HTTP/1.1" 302 0
[22/Oct/2015 17:01:07] "GET /admin/auth/user/2/ HTTP/1.1" 200 15613
[22/Oct/2015 17:01:07] "GET /static/admin/js/SelectBox.js HTTP/1.1" 200 4222
[22/Oct/2015 17:01:07] "GET /static/admin/js/SelectFilter2.js HTTP/1.1" 200 10127
[22/Oct/2015 17:01:07] "GET /admin/jsi18n/ HTTP/1.1" 200 6408
[22/Oct/2015 17:01:07] "GET /static/admin/js/admin/DateTimeShortcuts.js HTTP/1.1" 200 17161
[22/Oct/2015 17:01:07] "GET /static/admin/js/calendar.js HTTP/1.1" 200 5969
[22/Oct/2015 17:01:07] "GET /static/admin/img/icon_success.gif HTTP/1.1" 200 341
[22/Oct/2015 17:01:07] "GET /static/admin/img/icon_deletelink.gif HTTP/1.1" 200 181
[22/Oct/2015 17:01:07] "GET /static/admin/img/icon_calendar.gif HTTP/1.1" 200 192
[22/Oct/2015 17:01:07] "GET /static/admin/img/icon_clock.gif HTTP/1.1" 200 390
[22/Oct/2015 17:01:07] "GET /static/admin/img/icon-unknown.gif HTTP/1.1" 200 130
[22/Oct/2015 17:01:07] "GET /static/admin/img/selector-search.gif HTTP/1.1" 200 552
[22/Oct/2015 17:01:07] "GET /static/admin/img/selector-icons.gif HTTP/1.1" 200 2771
[22/Oct/2015 17:01:46] "GET /admin/ HTTP/1.1" 200 6429
[22/Oct/2015 17:01:46] "GET /static/admin/css/base.css HTTP/1.1" 304 0
[22/Oct/2015 17:01:46] "GET /static/admin/css/dashboard.css HTTP/1.1" 304 0
[22/Oct/2015 17:01:46] "GET /static/admin/img/default-bg.gif HTTP/1.1" 304 0
[22/Oct/2015 17:01:46] "GET /static/admin/img/icon_addlink.gif HTTP/1.1" 304 0
[22/Oct/2015 17:01:46] "GET /static/admin/img/icon_changelink.gif HTTP/1.1" 304 0
[22/Oct/2015 17:01:46] "GET /static/admin/img/nav-bg.gif HTTP/1.1" 304 0
[22/Oct/2015 17:01:51] "GET /admin/auth/group/ HTTP/1.1" 200 3639
[22/Oct/2015 17:01:51] "GET /static/admin/css/changelists.css HTTP/1.1" 304 0
[22/Oct/2015 17:01:51] "GET /static/admin/js/core.js HTTP/1.1" 304 0
[22/Oct/2015 17:01:51] "GET /static/admin/js/jquery.init.js HTTP/1.1" 304 0
[22/Oct/2015 17:01:51] "GET /static/admin/js/admin/RelatedObjectLookups.js HTTP/1.1" 304 0
[22/Oct/2015 17:01:51] "GET /static/admin/js/jquery.js HTTP/1.1" 304 0
[22/Oct/2015 17:01:51] "GET /static/admin/js/actions.js HTTP/1.1" 304 0
[22/Oct/2015 17:01:51] "GET /admin/jsi18n/ HTTP/1.1" 200 6408
[22/Oct/2015 17:01:51] "GET /static/admin/img/icon_searchbox.png HTTP/1.1" 304 0
[22/Oct/2015 17:01:51] "GET /static/admin/img/tooltag-add.png HTTP/1.1" 304 0
[22/Oct/2015 17:01:51] "GET /static/admin/img/nav-bg-reverse.gif HTTP/1.1" 304 0
[22/Oct/2015 17:01:55] "GET /admin/auth/group/add/ HTTP/1.1" 200 7757
[22/Oct/2015 17:01:55] "GET /static/admin/css/forms.css HTTP/1.1" 304 0
[22/Oct/2015 17:01:55] "GET /admin/jsi18n/ HTTP/1.1" 200 6408
[22/Oct/2015 17:01:55] "GET /static/admin/js/related-widget-wrapper.js HTTP/1.1" 304 0
[22/Oct/2015 17:01:55] "GET /static/admin/css/widgets.css HTTP/1.1" 304 0
[22/Oct/2015 17:02:42] "POST /admin/auth/group/add/ HTTP/1.1" 302 0
[22/Oct/2015 17:02:42] "GET /admin/auth/group/1/ HTTP/1.1" 200 8788
[22/Oct/2015 17:02:42] "GET /admin/jsi18n/ HTTP/1.1" 200 6408
[22/Oct/2015 17:02:52] "GET /static/admin/img/default-bg-reverse.gif HTTP/1.1" 200 835
[22/Oct/2015 17:02:52] "POST /admin/auth/group/1/ HTTP/1.1" 302 0
[22/Oct/2015 17:02:52] "GET /admin/auth/group/ HTTP/1.1" 200 4974
[22/Oct/2015 17:02:52] "GET /admin/jsi18n/ HTTP/1.1" 200 6408
[22/Oct/2015 17:02:55] "GET /admin/auth/group/1/ HTTP/1.1" 200 8618
[22/Oct/2015 17:02:55] "GET /admin/jsi18n/ HTTP/1.1" 200 6408
[22/Oct/2015 17:03:06] "GET /admin/ HTTP/1.1" 200 6984
[22/Oct/2015 17:03:09] "GET /admin/auth/user/ HTTP/1.1" 200 7148
[22/Oct/2015 17:03:09] "GET /admin/jsi18n/ HTTP/1.1" 200 6408
[22/Oct/2015 17:03:09] "GET /static/admin/img/icon-no.gif HTTP/1.1" 200 176
[22/Oct/2015 17:03:09] "GET /static/admin/img/icon-yes.gif HTTP/1.1" 304 0
[22/Oct/2015 17:03:09] "GET /static/admin/img/changelist-bg.gif HTTP/1.1" 304 0
[22/Oct/2015 17:03:09] "GET /static/admin/img/nav-bg-selected.gif HTTP/1.1" 304 0
[22/Oct/2015 17:03:09] "GET /static/admin/img/sorting-icons.gif HTTP/1.1" 304 0
[22/Oct/2015 17:03:12] "GET /admin/auth/user/2/ HTTP/1.1" 200 15472
[22/Oct/2015 17:03:12] "GET /static/admin/js/SelectBox.js HTTP/1.1" 304 0
[22/Oct/2015 17:03:12] "GET /static/admin/js/admin/DateTimeShortcuts.js HTTP/1.1" 304 0
[22/Oct/2015 17:03:12] "GET /static/admin/js/calendar.js HTTP/1.1" 304 0
[22/Oct/2015 17:03:12] "GET /static/admin/js/SelectFilter2.js HTTP/1.1" 304 0
[22/Oct/2015 17:03:12] "GET /admin/jsi18n/ HTTP/1.1" 200 6408
[22/Oct/2015 17:03:12] "GET /static/admin/img/icon_deletelink.gif HTTP/1.1" 304 0
[22/Oct/2015 17:03:12] "GET /static/admin/img/icon_calendar.gif HTTP/1.1" 304 0
[22/Oct/2015 17:03:12] "GET /static/admin/img/icon_clock.gif HTTP/1.1" 304 0
[22/Oct/2015 17:03:12] "GET /static/admin/img/icon-unknown.gif HTTP/1.1" 304 0
[22/Oct/2015 17:03:12] "GET /static/admin/img/selector-search.gif HTTP/1.1" 304 0
[22/Oct/2015 17:03:12] "GET /static/admin/img/selector-icons.gif HTTP/1.1" 304 0
[22/Oct/2015 17:03:57] "POST /admin/auth/user/2/ HTTP/1.1" 302 0
[22/Oct/2015 17:03:57] "GET /admin/auth/user/ HTTP/1.1" 200 7301
[22/Oct/2015 17:03:57] "GET /static/admin/css/base.css HTTP/1.1" 304 0
[22/Oct/2015 17:03:57] "GET /static/admin/css/changelists.css HTTP/1.1" 304 0
[22/Oct/2015 17:03:57] "GET /static/admin/js/admin/RelatedObjectLookups.js HTTP/1.1" 304 0
[22/Oct/2015 17:03:57] "GET /static/admin/js/core.js HTTP/1.1" 304 0
[22/Oct/2015 17:03:57] "GET /static/admin/js/jquery.js HTTP/1.1" 304 0
[22/Oct/2015 17:03:57] "GET /static/admin/js/jquery.init.js HTTP/1.1" 304 0
[22/Oct/2015 17:03:57] "GET /static/admin/js/actions.js HTTP/1.1" 304 0
[22/Oct/2015 17:03:57] "GET /admin/jsi18n/ HTTP/1.1" 200 6408
[22/Oct/2015 17:03:58] "GET /static/admin/img/icon_searchbox.png HTTP/1.1" 304 0
[22/Oct/2015 17:03:58] "GET /static/admin/img/nav-bg-reverse.gif HTTP/1.1" 304 0
[22/Oct/2015 17:03:58] "GET /static/admin/img/tooltag-add.png HTTP/1.1" 304 0
[22/Oct/2015 17:03:58] "GET /static/admin/img/nav-bg.gif HTTP/1.1" 304 0
[22/Oct/2015 17:03:58] "GET /static/admin/img/default-bg.gif HTTP/1.1" 304 0
[22/Oct/2015 17:03:58] "GET /static/admin/img/icon_success.gif HTTP/1.1" 304 0
[22/Oct/2015 17:04:05] "GET /admin/auth/user/2/ HTTP/1.1" 200 15474
[22/Oct/2015 17:04:06] "GET /static/admin/css/forms.css HTTP/1.1" 304 0
[22/Oct/2015 17:04:06] "GET /admin/jsi18n/ HTTP/1.1" 200 6408
[22/Oct/2015 17:04:06] "GET /static/admin/js/related-widget-wrapper.js HTTP/1.1" 304 0
[22/Oct/2015 17:04:06] "GET /static/admin/css/widgets.css HTTP/1.1" 304 0
[22/Oct/2015 17:04:06] "GET /static/admin/img/icon_addlink.gif HTTP/1.1" 304 0
[22/Oct/2015 17:04:14] "POST /admin/auth/user/2/ HTTP/1.1" 302 0
[22/Oct/2015 17:04:14] "GET /admin/auth/user/ HTTP/1.1" 200 7301
[22/Oct/2015 17:04:14] "GET /admin/jsi18n/ HTTP/1.1" 200 6408
[22/Oct/2015 17:04:22] "GET /admin/logout/ HTTP/1.1" 200 1642
[22/Oct/2015 17:04:26] "GET /admin/logout/ HTTP/1.1" 302 0
[22/Oct/2015 17:04:26] "GET /admin/ HTTP/1.1" 302 0
[22/Oct/2015 17:04:26] "GET /admin/login/?next=/admin/ HTTP/1.1" 200 1963
[22/Oct/2015 17:04:26] "GET /static/admin/css/login.css HTTP/1.1" 304 0
[22/Oct/2015 17:04:34] "GET /Login/ HTTP/1.1" 200 2122
[22/Oct/2015 17:04:34] "GET /static/img/logo.png HTTP/1.1" 404 1649
[22/Oct/2015 17:04:49] "POST /Login/ HTTP/1.1" 302 0
[22/Oct/2015 17:04:49] "GET /control HTTP/1.1" 301 0
[22/Oct/2015 17:04:49] "GET /control/ HTTP/1.1" 200 7340
[22/Oct/2015 17:04:49] "GET /static/img/logo.png HTTP/1.1" 404 1649
[22/Oct/2015 17:04:58] "GET /admin/ HTTP/1.1" 302 0
[22/Oct/2015 17:04:58] "GET /admin/login/?next=/admin/ HTTP/1.1" 200 1963
[22/Oct/2015 17:05:09] "POST /admin/login/?next=/admin/ HTTP/1.1" 200 2165
[22/Oct/2015 17:05:09] "GET /static/admin/img/icon_error.gif HTTP/1.1" 304 0
[22/Oct/2015 17:05:21] "POST /admin/login/?next=/admin/ HTTP/1.1" 302 0
[22/Oct/2015 17:05:21] "GET /admin/ HTTP/1.1" 200 7554
[22/Oct/2015 17:05:21] "GET /static/admin/css/dashboard.css HTTP/1.1" 304 0
[22/Oct/2015 17:05:21] "GET /static/admin/img/icon_changelink.gif HTTP/1.1" 304 0
[22/Oct/2015 17:05:27] "GET /admin/auth/user/ HTTP/1.1" 200 7148
[22/Oct/2015 17:05:27] "GET /admin/jsi18n/ HTTP/1.1" 200 6408
[22/Oct/2015 17:05:27] "GET /static/admin/img/icon-yes.gif HTTP/1.1" 304 0
[22/Oct/2015 17:05:27] "GET /static/admin/img/icon-no.gif HTTP/1.1" 304 0
[22/Oct/2015 17:05:27] "GET /static/admin/img/changelist-bg.gif HTTP/1.1" 304 0
[22/Oct/2015 17:05:27] "GET /static/admin/img/nav-bg-selected.gif HTTP/1.1" 304 0
[22/Oct/2015 17:05:27] "GET /static/admin/img/sorting-icons.gif HTTP/1.1" 304 0
[22/Oct/2015 17:05:30] "GET /admin/auth/user/1/ HTTP/1.1" 200 15552
[22/Oct/2015 17:05:30] "GET /admin/jsi18n/ HTTP/1.1" 200 6408
[22/Oct/2015 17:05:30] "GET /static/admin/js/SelectFilter2.js HTTP/1.1" 304 0
[22/Oct/2015 17:05:30] "GET /static/admin/js/calendar.js HTTP/1.1" 304 0
[22/Oct/2015 17:05:30] "GET /static/admin/js/admin/DateTimeShortcuts.js HTTP/1.1" 304 0
[22/Oct/2015 17:05:30] "GET /static/admin/js/SelectBox.js HTTP/1.1" 304 0
[22/Oct/2015 17:05:30] "GET /static/admin/img/icon_deletelink.gif HTTP/1.1" 304 0
[22/Oct/2015 17:05:30] "GET /static/admin/img/selector-search.gif HTTP/1.1" 304 0
[22/Oct/2015 17:05:30] "GET /static/admin/img/selector-icons.gif HTTP/1.1" 304 0
[22/Oct/2015 17:05:30] "GET /static/admin/img/icon_calendar.gif HTTP/1.1" 304 0
[22/Oct/2015 17:05:30] "GET /static/admin/img/icon_clock.gif HTTP/1.1" 304 0
[22/Oct/2015 17:05:30] "GET /static/admin/img/icon-unknown.gif HTTP/1.1" 304 0
[22/Oct/2015 17:05:39] "GET /admin/logout/ HTTP/1.1" 200 1642
Performing system checks...

System check identified no issues (0 silenced).
November 02, 2015 - 16:03:42
Django version 1.8.5, using settings 'pdvsa.settings'
Starting development server at http://127.7.7.1:8000/
Quit the server with CONTROL-C.
/home/joseagraz/Documentos/pdvsa-t-d/pdvsa/urls.py:8: RemovedInDjango19Warning: Default value of 'RedirectView.permanent' will change from True to False in Django 1.9. Set an explicit value to silence this warning.
  url(r'^$', RedirectView.as_view(url=reverse_lazy('login'))),

[02/Nov/2015 16:05:23] "GET /Login/ HTTP/1.1" 200 2122
[02/Nov/2015 16:05:24] "GET /static/css/login.css HTTP/1.1" 200 1881
[02/Nov/2015 16:05:24] "GET /static/js/bootstrap.min.js HTTP/1.1" 200 35951
[02/Nov/2015 16:05:24] "GET /static/js/jquery-1.11.2.min.js HTTP/1.1" 200 95931
[02/Nov/2015 16:05:24] "GET /static/css/base.css HTTP/1.1" 200 4118
[02/Nov/2015 16:05:24] "GET /static/img/Logo2.png HTTP/1.1" 200 1234
[02/Nov/2015 16:05:24] "GET /static/css/bootstrap.min.css HTTP/1.1" 200 117305
[02/Nov/2015 16:05:24] "GET /static/img/header_corazon.gif HTTP/1.1" 200 10910
[02/Nov/2015 16:05:24] "GET /static/img/fondo.jpg HTTP/1.1" 200 11008
[02/Nov/2015 16:05:24] "GET /static/img/ribbon.png HTTP/1.1" 200 171
[02/Nov/2015 16:05:24] "GET /static/img/ribbon-2.png HTTP/1.1" 200 166
[02/Nov/2015 16:05:24] "GET /static/img/logo.png HTTP/1.1" 404 1649
[02/Nov/2015 16:05:24] "GET /static/fonts/glyphicons-halflings-regular.woff2 HTTP/1.1" 200 18028
[02/Nov/2015 16:05:55] "POST /Login/ HTTP/1.1" 302 0
[02/Nov/2015 16:05:55] "GET /control HTTP/1.1" 301 0
[02/Nov/2015 16:05:55] "GET /control/ HTTP/1.1" 200 7340
[02/Nov/2015 16:05:55] "GET /static/img/logo.png HTTP/1.1" 404 1649
[02/Nov/2015 16:05:55] "GET /static/css/dashboard.css HTTP/1.1" 200 1453
[02/Nov/2015 16:05:55] "GET /static/css/bootstrapValidator.min.css HTTP/1.1" 200 565
[02/Nov/2015 16:05:55] "GET /static/css/dataTables.bootstrap.css HTTP/1.1" 200 8829
[02/Nov/2015 16:05:55] "GET /static/css/bootstrap-datetimepicker.css HTTP/1.1" 200 8860
[02/Nov/2015 16:05:55] "GET /static/css/bootstrap-toggle.min.css HTTP/1.1" 200 1590
[02/Nov/2015 16:05:55] "GET /static/js/dataTables.bootstrap.js HTTP/1.1" 200 4287
[02/Nov/2015 16:05:55] "GET /static/js/holder.js HTTP/1.1" 200 23861
[02/Nov/2015 16:05:55] "GET /static/js/dataTables.tableTools.js HTTP/1.1" 200 84590
[02/Nov/2015 16:05:55] "GET /static/js/jquery.dataTables.min.js HTTP/1.1" 200 79457
[02/Nov/2015 16:05:55] "GET /static/js/bootstrapValidator.min.js HTTP/1.1" 200 103316
[02/Nov/2015 16:05:56] "GET /static/js/bootstrap-toggle.min.js HTTP/1.1" 200 4129
[02/Nov/2015 16:05:56] "GET /static/css/lib/select2/select2.css HTTP/1.1" 200 17062
[02/Nov/2015 16:05:56] "GET /static/js/bootstrap-datetimepicker.js HTTP/1.1" 200 79208
[02/Nov/2015 16:05:56] "GET /static/js/base.js HTTP/1.1" 200 4238
[02/Nov/2015 16:05:56] "GET /static/js/moment.js HTTP/1.1" 200 348978
[02/Nov/2015 16:05:56] "GET /static/img/chavez1.jpeg HTTP/1.1" 200 22283
[02/Nov/2015 16:05:56] "GET /static/js/lib/select2/select2.js HTTP/1.1" 200 132348
[02/Nov/2015 16:07:15] "GET /logout/ HTTP/1.1" 302 0
[02/Nov/2015 16:07:15] "GET /Login HTTP/1.1" 301 0
[02/Nov/2015 16:07:15] "GET /Login/ HTTP/1.1" 200 2122
[02/Nov/2015 16:07:15] "GET /static/img/logo.png HTTP/1.1" 404 1649
[02/Nov/2015 16:07:23] "GET /admin/ HTTP/1.1" 302 0
[02/Nov/2015 16:07:23] "GET /admin/login/?next=/admin/ HTTP/1.1" 200 1963
[02/Nov/2015 16:07:23] "GET /static/admin/css/base.css HTTP/1.1" 200 14049
[02/Nov/2015 16:07:23] "GET /static/admin/css/login.css HTTP/1.1" 200 940
[02/Nov/2015 16:07:23] "GET /static/admin/img/nav-bg.gif HTTP/1.1" 200 265
[02/Nov/2015 16:07:23] "GET /favicon.ico HTTP/1.1" 404 2392
[02/Nov/2015 16:07:23] "GET /favicon.ico HTTP/1.1" 404 2392
[02/Nov/2015 16:07:25] "GET /static/admin/img/nav-bg-reverse.gif HTTP/1.1" 200 178
[02/Nov/2015 16:07:26] "POST /admin/login/?next=/admin/ HTTP/1.1" 302 0
[02/Nov/2015 16:07:26] "GET /admin/ HTTP/1.1" 200 7554
[02/Nov/2015 16:07:26] "GET /static/admin/css/dashboard.css HTTP/1.1" 200 434
[02/Nov/2015 16:07:26] "GET /static/admin/img/default-bg.gif HTTP/1.1" 200 836
[02/Nov/2015 16:07:26] "GET /static/admin/img/icon_changelink.gif HTTP/1.1" 200 119
[02/Nov/2015 16:07:26] "GET /static/admin/img/icon_addlink.gif HTTP/1.1" 200 119
[02/Nov/2015 16:07:38] "GET /admin/logout/ HTTP/1.1" 200 1642
Unhandled exception in thread started by <function wrapper at 0x7fdc2b080938>
Traceback (most recent call last):
  File "/home/joseagraz/Documentos/pdvsatydenv/local/lib/python2.7/site-packages/django/utils/autoreload.py", line 229, in wrapper
    fn(*args, **kwargs)
  File "/home/joseagraz/Documentos/pdvsatydenv/local/lib/python2.7/site-packages/django/core/management/commands/runserver.py", line 107, in inner_run
    autoreload.raise_last_exception()
  File "/home/joseagraz/Documentos/pdvsatydenv/local/lib/python2.7/site-packages/django/utils/autoreload.py", line 252, in raise_last_exception
    six.reraise(*_exception)
  File "/home/joseagraz/Documentos/pdvsatydenv/local/lib/python2.7/site-packages/django/utils/autoreload.py", line 229, in wrapper
    fn(*args, **kwargs)
  File "/home/joseagraz/Documentos/pdvsatydenv/local/lib/python2.7/site-packages/django/__init__.py", line 18, in setup
    apps.populate(settings.INSTALLED_APPS)
  File "/home/joseagraz/Documentos/pdvsatydenv/local/lib/python2.7/site-packages/django/apps/registry.py", line 108, in populate
    app_config.import_models(all_models)
  File "/home/joseagraz/Documentos/pdvsatydenv/local/lib/python2.7/site-packages/django/apps/config.py", line 198, in import_models
    self.models_module = import_module(models_module_name)
  File "/usr/lib/python2.7/importlib/__init__.py", line 37, in import_module
    __import__(name)
  File "/home/joseagraz/Documentos/pdvsatydenv/local/lib/python2.7/site-packages/django/contrib/auth/models.py", line 41, in <module>
    class Permission(models.Model):
  File "/home/joseagraz/Documentos/pdvsatydenv/local/lib/python2.7/site-packages/django/db/models/base.py", line 139, in __new__
    new_class.add_to_class('_meta', Options(meta, **kwargs))
  File "/home/joseagraz/Documentos/pdvsatydenv/local/lib/python2.7/site-packages/django/db/models/base.py", line 324, in add_to_class
    value.contribute_to_class(cls, name)
  File "/home/joseagraz/Documentos/pdvsatydenv/local/lib/python2.7/site-packages/django/db/models/options.py", line 250, in contribute_to_class
    self.db_table = truncate_name(self.db_table, connection.ops.max_name_length())
  File "/home/joseagraz/Documentos/pdvsatydenv/local/lib/python2.7/site-packages/django/db/__init__.py", line 36, in __getattr__
    return getattr(connections[DEFAULT_DB_ALIAS], item)
  File "/home/joseagraz/Documentos/pdvsatydenv/local/lib/python2.7/site-packages/django/db/utils.py", line 240, in __getitem__
    backend = load_backend(db['ENGINE'])
  File "/home/joseagraz/Documentos/pdvsatydenv/local/lib/python2.7/site-packages/django/db/utils.py", line 111, in load_backend
    return import_module('%s.base' % backend_name)
  File "/usr/lib/python2.7/importlib/__init__.py", line 37, in import_module
    __import__(name)
  File "/home/joseagraz/Documentos/pdvsatydenv/local/lib/python2.7/site-packages/django/db/backends/mysql/base.py", line 27, in <module>
    raise ImproperlyConfigured("Error loading MySQLdb module: %s" % e)
django.core.exceptions.ImproperlyConfigured: Error loading MySQLdb module: libmysqlclient.so.18: cannot open shared object file: No such file or directory
Unhandled exception in thread started by <function wrapper at 0x7fe68f896938>
Traceback (most recent call last):
  File "/home/joseagraz/Documentos/pdvsatydenv/local/lib/python2.7/site-packages/django/utils/autoreload.py", line 229, in wrapper
    fn(*args, **kwargs)
  File "/home/joseagraz/Documentos/pdvsatydenv/local/lib/python2.7/site-packages/django/core/management/commands/runserver.py", line 107, in inner_run
    autoreload.raise_last_exception()
  File "/home/joseagraz/Documentos/pdvsatydenv/local/lib/python2.7/site-packages/django/utils/autoreload.py", line 252, in raise_last_exception
    six.reraise(*_exception)
  File "/home/joseagraz/Documentos/pdvsatydenv/local/lib/python2.7/site-packages/django/utils/autoreload.py", line 229, in wrapper
    fn(*args, **kwargs)
  File "/home/joseagraz/Documentos/pdvsatydenv/local/lib/python2.7/site-packages/django/__init__.py", line 18, in setup
    apps.populate(settings.INSTALLED_APPS)
  File "/home/joseagraz/Documentos/pdvsatydenv/local/lib/python2.7/site-packages/django/apps/registry.py", line 108, in populate
    app_config.import_models(all_models)
  File "/home/joseagraz/Documentos/pdvsatydenv/local/lib/python2.7/site-packages/django/apps/config.py", line 198, in import_models
    self.models_module = import_module(models_module_name)
  File "/usr/lib/python2.7/importlib/__init__.py", line 37, in import_module
    __import__(name)
  File "/home/joseagraz/Documentos/pdvsatydenv/local/lib/python2.7/site-packages/django/contrib/auth/models.py", line 41, in <module>
    class Permission(models.Model):
  File "/home/joseagraz/Documentos/pdvsatydenv/local/lib/python2.7/site-packages/django/db/models/base.py", line 139, in __new__
    new_class.add_to_class('_meta', Options(meta, **kwargs))
  File "/home/joseagraz/Documentos/pdvsatydenv/local/lib/python2.7/site-packages/django/db/models/base.py", line 324, in add_to_class
    value.contribute_to_class(cls, name)
  File "/home/joseagraz/Documentos/pdvsatydenv/local/lib/python2.7/site-packages/django/db/models/options.py", line 250, in contribute_to_class
    self.db_table = truncate_name(self.db_table, connection.ops.max_name_length())
  File "/home/joseagraz/Documentos/pdvsatydenv/local/lib/python2.7/site-packages/django/db/__init__.py", line 36, in __getattr__
    return getattr(connections[DEFAULT_DB_ALIAS], item)
  File "/home/joseagraz/Documentos/pdvsatydenv/local/lib/python2.7/site-packages/django/db/utils.py", line 240, in __getitem__
    backend = load_backend(db['ENGINE'])
  File "/home/joseagraz/Documentos/pdvsatydenv/local/lib/python2.7/site-packages/django/db/utils.py", line 111, in load_backend
    return import_module('%s.base' % backend_name)
  File "/usr/lib/python2.7/importlib/__init__.py", line 37, in import_module
    __import__(name)
  File "/home/joseagraz/Documentos/pdvsatydenv/local/lib/python2.7/site-packages/django/db/backends/mysql/base.py", line 27, in <module>
    raise ImproperlyConfigured("Error loading MySQLdb module: %s" % e)
django.core.exceptions.ImproperlyConfigured: Error loading MySQLdb module: libmysqlclient.so.18: cannot open shared object file: No such file or directory
Unhandled exception in thread started by <function wrapper at 0x7f6c4911f938>
Traceback (most recent call last):
  File "/home/joseagraz/Documentos/pdvsatydenv/local/lib/python2.7/site-packages/django/utils/autoreload.py", line 229, in wrapper
    fn(*args, **kwargs)
  File "/home/joseagraz/Documentos/pdvsatydenv/local/lib/python2.7/site-packages/django/core/management/commands/runserver.py", line 107, in inner_run
    autoreload.raise_last_exception()
  File "/home/joseagraz/Documentos/pdvsatydenv/local/lib/python2.7/site-packages/django/utils/autoreload.py", line 252, in raise_last_exception
    six.reraise(*_exception)
  File "/home/joseagraz/Documentos/pdvsatydenv/local/lib/python2.7/site-packages/django/utils/autoreload.py", line 229, in wrapper
    fn(*args, **kwargs)
  File "/home/joseagraz/Documentos/pdvsatydenv/local/lib/python2.7/site-packages/django/__init__.py", line 18, in setup
    apps.populate(settings.INSTALLED_APPS)
  File "/home/joseagraz/Documentos/pdvsatydenv/local/lib/python2.7/site-packages/django/apps/registry.py", line 108, in populate
    app_config.import_models(all_models)
  File "/home/joseagraz/Documentos/pdvsatydenv/local/lib/python2.7/site-packages/django/apps/config.py", line 198, in import_models
    self.models_module = import_module(models_module_name)
  File "/usr/lib/python2.7/importlib/__init__.py", line 37, in import_module
    __import__(name)
  File "/home/joseagraz/Documentos/pdvsatydenv/local/lib/python2.7/site-packages/django/contrib/auth/models.py", line 41, in <module>
    class Permission(models.Model):
  File "/home/joseagraz/Documentos/pdvsatydenv/local/lib/python2.7/site-packages/django/db/models/base.py", line 139, in __new__
    new_class.add_to_class('_meta', Options(meta, **kwargs))
  File "/home/joseagraz/Documentos/pdvsatydenv/local/lib/python2.7/site-packages/django/db/models/base.py", line 324, in add_to_class
    value.contribute_to_class(cls, name)
  File "/home/joseagraz/Documentos/pdvsatydenv/local/lib/python2.7/site-packages/django/db/models/options.py", line 250, in contribute_to_class
    self.db_table = truncate_name(self.db_table, connection.ops.max_name_length())
  File "/home/joseagraz/Documentos/pdvsatydenv/local/lib/python2.7/site-packages/django/db/__init__.py", line 36, in __getattr__
    return getattr(connections[DEFAULT_DB_ALIAS], item)
  File "/home/joseagraz/Documentos/pdvsatydenv/local/lib/python2.7/site-packages/django/db/utils.py", line 240, in __getitem__
    backend = load_backend(db['ENGINE'])
  File "/home/joseagraz/Documentos/pdvsatydenv/local/lib/python2.7/site-packages/django/db/utils.py", line 111, in load_backend
    return import_module('%s.base' % backend_name)
  File "/usr/lib/python2.7/importlib/__init__.py", line 37, in import_module
    __import__(name)
  File "/home/joseagraz/Documentos/pdvsatydenv/local/lib/python2.7/site-packages/django/db/backends/mysql/base.py", line 27, in <module>
    raise ImproperlyConfigured("Error loading MySQLdb module: %s" % e)
django.core.exceptions.ImproperlyConfigured: Error loading MySQLdb module: libmysqlclient.so.18: cannot open shared object file: No such file or directory
Unhandled exception in thread started by <function wrapper at 0x7fdc03cbd938>
Traceback (most recent call last):
  File "/home/joseagraz/Documentos/pdvsatydenv/local/lib/python2.7/site-packages/django/utils/autoreload.py", line 229, in wrapper
    fn(*args, **kwargs)
  File "/home/joseagraz/Documentos/pdvsatydenv/local/lib/python2.7/site-packages/django/core/management/commands/runserver.py", line 107, in inner_run
    autoreload.raise_last_exception()
  File "/home/joseagraz/Documentos/pdvsatydenv/local/lib/python2.7/site-packages/django/utils/autoreload.py", line 252, in raise_last_exception
    six.reraise(*_exception)
  File "/home/joseagraz/Documentos/pdvsatydenv/local/lib/python2.7/site-packages/django/utils/autoreload.py", line 229, in wrapper
    fn(*args, **kwargs)
  File "/home/joseagraz/Documentos/pdvsatydenv/local/lib/python2.7/site-packages/django/__init__.py", line 18, in setup
    apps.populate(settings.INSTALLED_APPS)
  File "/home/joseagraz/Documentos/pdvsatydenv/local/lib/python2.7/site-packages/django/apps/registry.py", line 108, in populate
    app_config.import_models(all_models)
  File "/home/joseagraz/Documentos/pdvsatydenv/local/lib/python2.7/site-packages/django/apps/config.py", line 198, in import_models
    self.models_module = import_module(models_module_name)
  File "/usr/lib/python2.7/importlib/__init__.py", line 37, in import_module
    __import__(name)
  File "/home/joseagraz/Documentos/pdvsatydenv/local/lib/python2.7/site-packages/django/contrib/auth/models.py", line 41, in <module>
    class Permission(models.Model):
  File "/home/joseagraz/Documentos/pdvsatydenv/local/lib/python2.7/site-packages/django/db/models/base.py", line 139, in __new__
    new_class.add_to_class('_meta', Options(meta, **kwargs))
  File "/home/joseagraz/Documentos/pdvsatydenv/local/lib/python2.7/site-packages/django/db/models/base.py", line 324, in add_to_class
    value.contribute_to_class(cls, name)
  File "/home/joseagraz/Documentos/pdvsatydenv/local/lib/python2.7/site-packages/django/db/models/options.py", line 250, in contribute_to_class
    self.db_table = truncate_name(self.db_table, connection.ops.max_name_length())
  File "/home/joseagraz/Documentos/pdvsatydenv/local/lib/python2.7/site-packages/django/db/__init__.py", line 36, in __getattr__
    return getattr(connections[DEFAULT_DB_ALIAS], item)
  File "/home/joseagraz/Documentos/pdvsatydenv/local/lib/python2.7/site-packages/django/db/utils.py", line 240, in __getitem__
    backend = load_backend(db['ENGINE'])
  File "/home/joseagraz/Documentos/pdvsatydenv/local/lib/python2.7/site-packages/django/db/utils.py", line 111, in load_backend
    return import_module('%s.base' % backend_name)
  File "/usr/lib/python2.7/importlib/__init__.py", line 37, in import_module
    __import__(name)
  File "/home/joseagraz/Documentos/pdvsatydenv/local/lib/python2.7/site-packages/django/db/backends/mysql/base.py", line 27, in <module>
    raise ImproperlyConfigured("Error loading MySQLdb module: %s" % e)
django.core.exceptions.ImproperlyConfigured: Error loading MySQLdb module: libmysqlclient.so.18: cannot open shared object file: No such file or directory
Unhandled exception in thread started by <function wrapper at 0x7f938a994aa0>
Traceback (most recent call last):
  File "/home/joseagraz/Documentos/pdvsaenvvv/local/lib/python2.7/site-packages/django/utils/autoreload.py", line 229, in wrapper
    fn(*args, **kwargs)
  File "/home/joseagraz/Documentos/pdvsaenvvv/local/lib/python2.7/site-packages/django/core/management/commands/runserver.py", line 107, in inner_run
    autoreload.raise_last_exception()
  File "/home/joseagraz/Documentos/pdvsaenvvv/local/lib/python2.7/site-packages/django/utils/autoreload.py", line 252, in raise_last_exception
    six.reraise(*_exception)
  File "/home/joseagraz/Documentos/pdvsaenvvv/local/lib/python2.7/site-packages/django/utils/autoreload.py", line 229, in wrapper
    fn(*args, **kwargs)
  File "/home/joseagraz/Documentos/pdvsaenvvv/local/lib/python2.7/site-packages/django/__init__.py", line 18, in setup
    apps.populate(settings.INSTALLED_APPS)
  File "/home/joseagraz/Documentos/pdvsaenvvv/local/lib/python2.7/site-packages/django/apps/registry.py", line 108, in populate
    app_config.import_models(all_models)
  File "/home/joseagraz/Documentos/pdvsaenvvv/local/lib/python2.7/site-packages/django/apps/config.py", line 198, in import_models
    self.models_module = import_module(models_module_name)
  File "/usr/lib/python2.7/importlib/__init__.py", line 37, in import_module
    __import__(name)
  File "/home/joseagraz/Documentos/pdvsaenvvv/local/lib/python2.7/site-packages/django/contrib/auth/models.py", line 41, in <module>
    class Permission(models.Model):
  File "/home/joseagraz/Documentos/pdvsaenvvv/local/lib/python2.7/site-packages/django/db/models/base.py", line 139, in __new__
    new_class.add_to_class('_meta', Options(meta, **kwargs))
  File "/home/joseagraz/Documentos/pdvsaenvvv/local/lib/python2.7/site-packages/django/db/models/base.py", line 324, in add_to_class
    value.contribute_to_class(cls, name)
  File "/home/joseagraz/Documentos/pdvsaenvvv/local/lib/python2.7/site-packages/django/db/models/options.py", line 250, in contribute_to_class
    self.db_table = truncate_name(self.db_table, connection.ops.max_name_length())
  File "/home/joseagraz/Documentos/pdvsaenvvv/local/lib/python2.7/site-packages/django/db/__init__.py", line 36, in __getattr__
    return getattr(connections[DEFAULT_DB_ALIAS], item)
  File "/home/joseagraz/Documentos/pdvsaenvvv/local/lib/python2.7/site-packages/django/db/utils.py", line 240, in __getitem__
    backend = load_backend(db['ENGINE'])
  File "/home/joseagraz/Documentos/pdvsaenvvv/local/lib/python2.7/site-packages/django/db/utils.py", line 111, in load_backend
    return import_module('%s.base' % backend_name)
  File "/usr/lib/python2.7/importlib/__init__.py", line 37, in import_module
    __import__(name)
  File "/home/joseagraz/Documentos/pdvsaenvvv/local/lib/python2.7/site-packages/django/db/backends/mysql/base.py", line 27, in <module>
    raise ImproperlyConfigured("Error loading MySQLdb module: %s" % e)
django.core.exceptions.ImproperlyConfigured: Error loading MySQLdb module: libmysqlclient.so.18: cannot open shared object file: No such file or directory
Unhandled exception in thread started by <function wrapper at 0x7ff0e2ddaaa0>
Traceback (most recent call last):
  File "/home/joseagraz/Documentos/pdvsaenvvv/local/lib/python2.7/site-packages/django/utils/autoreload.py", line 229, in wrapper
    fn(*args, **kwargs)
  File "/home/joseagraz/Documentos/pdvsaenvvv/local/lib/python2.7/site-packages/django/core/management/commands/runserver.py", line 107, in inner_run
    autoreload.raise_last_exception()
  File "/home/joseagraz/Documentos/pdvsaenvvv/local/lib/python2.7/site-packages/django/utils/autoreload.py", line 252, in raise_last_exception
    six.reraise(*_exception)
  File "/home/joseagraz/Documentos/pdvsaenvvv/local/lib/python2.7/site-packages/django/utils/autoreload.py", line 229, in wrapper
    fn(*args, **kwargs)
  File "/home/joseagraz/Documentos/pdvsaenvvv/local/lib/python2.7/site-packages/django/__init__.py", line 18, in setup
    apps.populate(settings.INSTALLED_APPS)
  File "/home/joseagraz/Documentos/pdvsaenvvv/local/lib/python2.7/site-packages/django/apps/registry.py", line 108, in populate
    app_config.import_models(all_models)
  File "/home/joseagraz/Documentos/pdvsaenvvv/local/lib/python2.7/site-packages/django/apps/config.py", line 198, in import_models
    self.models_module = import_module(models_module_name)
  File "/usr/lib/python2.7/importlib/__init__.py", line 37, in import_module
    __import__(name)
  File "/home/joseagraz/Documentos/pdvsaenvvv/local/lib/python2.7/site-packages/django/contrib/auth/models.py", line 41, in <module>
    class Permission(models.Model):
  File "/home/joseagraz/Documentos/pdvsaenvvv/local/lib/python2.7/site-packages/django/db/models/base.py", line 139, in __new__
    new_class.add_to_class('_meta', Options(meta, **kwargs))
  File "/home/joseagraz/Documentos/pdvsaenvvv/local/lib/python2.7/site-packages/django/db/models/base.py", line 324, in add_to_class
    value.contribute_to_class(cls, name)
  File "/home/joseagraz/Documentos/pdvsaenvvv/local/lib/python2.7/site-packages/django/db/models/options.py", line 250, in contribute_to_class
    self.db_table = truncate_name(self.db_table, connection.ops.max_name_length())
  File "/home/joseagraz/Documentos/pdvsaenvvv/local/lib/python2.7/site-packages/django/db/__init__.py", line 36, in __getattr__
    return getattr(connections[DEFAULT_DB_ALIAS], item)
  File "/home/joseagraz/Documentos/pdvsaenvvv/local/lib/python2.7/site-packages/django/db/utils.py", line 240, in __getitem__
    backend = load_backend(db['ENGINE'])
  File "/home/joseagraz/Documentos/pdvsaenvvv/local/lib/python2.7/site-packages/django/db/utils.py", line 111, in load_backend
    return import_module('%s.base' % backend_name)
  File "/usr/lib/python2.7/importlib/__init__.py", line 37, in import_module
    __import__(name)
  File "/home/joseagraz/Documentos/pdvsaenvvv/local/lib/python2.7/site-packages/django/db/backends/mysql/base.py", line 27, in <module>
    raise ImproperlyConfigured("Error loading MySQLdb module: %s" % e)
django.core.exceptions.ImproperlyConfigured: Error loading MySQLdb module: libmysqlclient.so.18: cannot open shared object file: No such file or directory
Unhandled exception in thread started by <function wrapper at 0x7fce2d0c3aa0>
Traceback (most recent call last):
  File "/home/joseagraz/Documentos/pdvsaenvvv/local/lib/python2.7/site-packages/django/utils/autoreload.py", line 229, in wrapper
    fn(*args, **kwargs)
  File "/home/joseagraz/Documentos/pdvsaenvvv/local/lib/python2.7/site-packages/django/core/management/commands/runserver.py", line 107, in inner_run
    autoreload.raise_last_exception()
  File "/home/joseagraz/Documentos/pdvsaenvvv/local/lib/python2.7/site-packages/django/utils/autoreload.py", line 252, in raise_last_exception
    six.reraise(*_exception)
  File "/home/joseagraz/Documentos/pdvsaenvvv/local/lib/python2.7/site-packages/django/utils/autoreload.py", line 229, in wrapper
    fn(*args, **kwargs)
  File "/home/joseagraz/Documentos/pdvsaenvvv/local/lib/python2.7/site-packages/django/__init__.py", line 18, in setup
    apps.populate(settings.INSTALLED_APPS)
  File "/home/joseagraz/Documentos/pdvsaenvvv/local/lib/python2.7/site-packages/django/apps/registry.py", line 108, in populate
    app_config.import_models(all_models)
  File "/home/joseagraz/Documentos/pdvsaenvvv/local/lib/python2.7/site-packages/django/apps/config.py", line 198, in import_models
    self.models_module = import_module(models_module_name)
  File "/usr/lib/python2.7/importlib/__init__.py", line 37, in import_module
    __import__(name)
  File "/home/joseagraz/Documentos/pdvsaenvvv/local/lib/python2.7/site-packages/django/contrib/auth/models.py", line 41, in <module>
    class Permission(models.Model):
  File "/home/joseagraz/Documentos/pdvsaenvvv/local/lib/python2.7/site-packages/django/db/models/base.py", line 139, in __new__
    new_class.add_to_class('_meta', Options(meta, **kwargs))
  File "/home/joseagraz/Documentos/pdvsaenvvv/local/lib/python2.7/site-packages/django/db/models/base.py", line 324, in add_to_class
    value.contribute_to_class(cls, name)
  File "/home/joseagraz/Documentos/pdvsaenvvv/local/lib/python2.7/site-packages/django/db/models/options.py", line 250, in contribute_to_class
    self.db_table = truncate_name(self.db_table, connection.ops.max_name_length())
  File "/home/joseagraz/Documentos/pdvsaenvvv/local/lib/python2.7/site-packages/django/db/__init__.py", line 36, in __getattr__
    return getattr(connections[DEFAULT_DB_ALIAS], item)
  File "/home/joseagraz/Documentos/pdvsaenvvv/local/lib/python2.7/site-packages/django/db/utils.py", line 240, in __getitem__
    backend = load_backend(db['ENGINE'])
  File "/home/joseagraz/Documentos/pdvsaenvvv/local/lib/python2.7/site-packages/django/db/utils.py", line 111, in load_backend
    return import_module('%s.base' % backend_name)
  File "/usr/lib/python2.7/importlib/__init__.py", line 37, in import_module
    __import__(name)
  File "/home/joseagraz/Documentos/pdvsaenvvv/local/lib/python2.7/site-packages/django/db/backends/mysql/base.py", line 27, in <module>
    raise ImproperlyConfigured("Error loading MySQLdb module: %s" % e)
django.core.exceptions.ImproperlyConfigured: Error loading MySQLdb module: libmysqlclient.so.18: cannot open shared object file: No such file or directory
Traceback (most recent call last):
  File "./manage.py", line 8, in <module>
    from django.core.management import execute_from_command_line
ImportError: No module named django.core.management
Traceback (most recent call last):
  File "./manage.py", line 8, in <module>
    from django.core.management import execute_from_command_line
ImportError: No module named django.core.management
Traceback (most recent call last):
  File "./manage.py", line 8, in <module>
    from django.core.management import execute_from_command_line
ImportError: No module named django.core.management
Unhandled exception in thread started by <function wrapper at 0x7f9790f34b90>
Traceback (most recent call last):
  File "/home/joseagraz/Documentos/pdvsaenv/local/lib/python2.7/site-packages/django/utils/autoreload.py", line 229, in wrapper
    fn(*args, **kwargs)
  File "/home/joseagraz/Documentos/pdvsaenv/local/lib/python2.7/site-packages/django/core/management/commands/runserver.py", line 107, in inner_run
    autoreload.raise_last_exception()
  File "/home/joseagraz/Documentos/pdvsaenv/local/lib/python2.7/site-packages/django/utils/autoreload.py", line 252, in raise_last_exception
    six.reraise(*_exception)
  File "/home/joseagraz/Documentos/pdvsaenv/local/lib/python2.7/site-packages/django/utils/autoreload.py", line 229, in wrapper
    fn(*args, **kwargs)
  File "/home/joseagraz/Documentos/pdvsaenv/local/lib/python2.7/site-packages/django/__init__.py", line 18, in setup
    apps.populate(settings.INSTALLED_APPS)
  File "/home/joseagraz/Documentos/pdvsaenv/local/lib/python2.7/site-packages/django/apps/registry.py", line 108, in populate
    app_config.import_models(all_models)
  File "/home/joseagraz/Documentos/pdvsaenv/local/lib/python2.7/site-packages/django/apps/config.py", line 198, in import_models
    self.models_module = import_module(models_module_name)
  File "/usr/lib/python2.7/importlib/__init__.py", line 37, in import_module
    __import__(name)
  File "/home/joseagraz/Documentos/pdvsaenv/local/lib/python2.7/site-packages/django/contrib/auth/models.py", line 41, in <module>
    class Permission(models.Model):
  File "/home/joseagraz/Documentos/pdvsaenv/local/lib/python2.7/site-packages/django/db/models/base.py", line 139, in __new__
    new_class.add_to_class('_meta', Options(meta, **kwargs))
  File "/home/joseagraz/Documentos/pdvsaenv/local/lib/python2.7/site-packages/django/db/models/base.py", line 324, in add_to_class
    value.contribute_to_class(cls, name)
  File "/home/joseagraz/Documentos/pdvsaenv/local/lib/python2.7/site-packages/django/db/models/options.py", line 250, in contribute_to_class
    self.db_table = truncate_name(self.db_table, connection.ops.max_name_length())
  File "/home/joseagraz/Documentos/pdvsaenv/local/lib/python2.7/site-packages/django/db/__init__.py", line 36, in __getattr__
    return getattr(connections[DEFAULT_DB_ALIAS], item)
  File "/home/joseagraz/Documentos/pdvsaenv/local/lib/python2.7/site-packages/django/db/utils.py", line 240, in __getitem__
    backend = load_backend(db['ENGINE'])
  File "/home/joseagraz/Documentos/pdvsaenv/local/lib/python2.7/site-packages/django/db/utils.py", line 111, in load_backend
    return import_module('%s.base' % backend_name)
  File "/usr/lib/python2.7/importlib/__init__.py", line 37, in import_module
    __import__(name)
  File "/home/joseagraz/Documentos/pdvsaenv/local/lib/python2.7/site-packages/django/db/backends/mysql/base.py", line 27, in <module>
    raise ImproperlyConfigured("Error loading MySQLdb module: %s" % e)
django.core.exceptions.ImproperlyConfigured: Error loading MySQLdb module: libmysqlclient.so.18: cannot open shared object file: No such file or directory
Unhandled exception in thread started by <function wrapper at 0x7faccde8bb90>
Traceback (most recent call last):
  File "/home/joseagraz/Documentos/pdvsaenv/local/lib/python2.7/site-packages/django/utils/autoreload.py", line 229, in wrapper
    fn(*args, **kwargs)
  File "/home/joseagraz/Documentos/pdvsaenv/local/lib/python2.7/site-packages/django/core/management/commands/runserver.py", line 107, in inner_run
    autoreload.raise_last_exception()
  File "/home/joseagraz/Documentos/pdvsaenv/local/lib/python2.7/site-packages/django/utils/autoreload.py", line 252, in raise_last_exception
    six.reraise(*_exception)
  File "/home/joseagraz/Documentos/pdvsaenv/local/lib/python2.7/site-packages/django/utils/autoreload.py", line 229, in wrapper
    fn(*args, **kwargs)
  File "/home/joseagraz/Documentos/pdvsaenv/local/lib/python2.7/site-packages/django/__init__.py", line 18, in setup
    apps.populate(settings.INSTALLED_APPS)
  File "/home/joseagraz/Documentos/pdvsaenv/local/lib/python2.7/site-packages/django/apps/registry.py", line 108, in populate
    app_config.import_models(all_models)
  File "/home/joseagraz/Documentos/pdvsaenv/local/lib/python2.7/site-packages/django/apps/config.py", line 198, in import_models
    self.models_module = import_module(models_module_name)
  File "/usr/lib/python2.7/importlib/__init__.py", line 37, in import_module
    __import__(name)
  File "/home/joseagraz/Documentos/pdvsaenv/local/lib/python2.7/site-packages/django/contrib/auth/models.py", line 41, in <module>
    class Permission(models.Model):
  File "/home/joseagraz/Documentos/pdvsaenv/local/lib/python2.7/site-packages/django/db/models/base.py", line 139, in __new__
    new_class.add_to_class('_meta', Options(meta, **kwargs))
  File "/home/joseagraz/Documentos/pdvsaenv/local/lib/python2.7/site-packages/django/db/models/base.py", line 324, in add_to_class
    value.contribute_to_class(cls, name)
  File "/home/joseagraz/Documentos/pdvsaenv/local/lib/python2.7/site-packages/django/db/models/options.py", line 250, in contribute_to_class
    self.db_table = truncate_name(self.db_table, connection.ops.max_name_length())
  File "/home/joseagraz/Documentos/pdvsaenv/local/lib/python2.7/site-packages/django/db/__init__.py", line 36, in __getattr__
    return getattr(connections[DEFAULT_DB_ALIAS], item)
  File "/home/joseagraz/Documentos/pdvsaenv/local/lib/python2.7/site-packages/django/db/utils.py", line 240, in __getitem__
    backend = load_backend(db['ENGINE'])
  File "/home/joseagraz/Documentos/pdvsaenv/local/lib/python2.7/site-packages/django/db/utils.py", line 111, in load_backend
    return import_module('%s.base' % backend_name)
  File "/usr/lib/python2.7/importlib/__init__.py", line 37, in import_module
    __import__(name)
  File "/home/joseagraz/Documentos/pdvsaenv/local/lib/python2.7/site-packages/django/db/backends/mysql/base.py", line 27, in <module>
    raise ImproperlyConfigured("Error loading MySQLdb module: %s" % e)
django.core.exceptions.ImproperlyConfigured: Error loading MySQLdb module: libmysqlclient.so.18: cannot open shared object file: No such file or directory
Unhandled exception in thread started by <function wrapper at 0x7f8c4e22ab90>
Traceback (most recent call last):
  File "/home/joseagraz/Documentos/pdvsaenv/local/lib/python2.7/site-packages/django/utils/autoreload.py", line 229, in wrapper
    fn(*args, **kwargs)
  File "/home/joseagraz/Documentos/pdvsaenv/local/lib/python2.7/site-packages/django/core/management/commands/runserver.py", line 107, in inner_run
    autoreload.raise_last_exception()
  File "/home/joseagraz/Documentos/pdvsaenv/local/lib/python2.7/site-packages/django/utils/autoreload.py", line 252, in raise_last_exception
    six.reraise(*_exception)
  File "/home/joseagraz/Documentos/pdvsaenv/local/lib/python2.7/site-packages/django/utils/autoreload.py", line 229, in wrapper
    fn(*args, **kwargs)
  File "/home/joseagraz/Documentos/pdvsaenv/local/lib/python2.7/site-packages/django/__init__.py", line 18, in setup
    apps.populate(settings.INSTALLED_APPS)
  File "/home/joseagraz/Documentos/pdvsaenv/local/lib/python2.7/site-packages/django/apps/registry.py", line 108, in populate
    app_config.import_models(all_models)
  File "/home/joseagraz/Documentos/pdvsaenv/local/lib/python2.7/site-packages/django/apps/config.py", line 198, in import_models
    self.models_module = import_module(models_module_name)
  File "/usr/lib/python2.7/importlib/__init__.py", line 37, in import_module
    __import__(name)
  File "/home/joseagraz/Documentos/pdvsaenv/local/lib/python2.7/site-packages/django/contrib/auth/models.py", line 41, in <module>
    class Permission(models.Model):
  File "/home/joseagraz/Documentos/pdvsaenv/local/lib/python2.7/site-packages/django/db/models/base.py", line 139, in __new__
    new_class.add_to_class('_meta', Options(meta, **kwargs))
  File "/home/joseagraz/Documentos/pdvsaenv/local/lib/python2.7/site-packages/django/db/models/base.py", line 324, in add_to_class
    value.contribute_to_class(cls, name)
  File "/home/joseagraz/Documentos/pdvsaenv/local/lib/python2.7/site-packages/django/db/models/options.py", line 250, in contribute_to_class
    self.db_table = truncate_name(self.db_table, connection.ops.max_name_length())
  File "/home/joseagraz/Documentos/pdvsaenv/local/lib/python2.7/site-packages/django/db/__init__.py", line 36, in __getattr__
    return getattr(connections[DEFAULT_DB_ALIAS], item)
  File "/home/joseagraz/Documentos/pdvsaenv/local/lib/python2.7/site-packages/django/db/utils.py", line 240, in __getitem__
    backend = load_backend(db['ENGINE'])
  File "/home/joseagraz/Documentos/pdvsaenv/local/lib/python2.7/site-packages/django/db/utils.py", line 111, in load_backend
    return import_module('%s.base' % backend_name)
  File "/usr/lib/python2.7/importlib/__init__.py", line 37, in import_module
    __import__(name)
  File "/home/joseagraz/Documentos/pdvsaenv/local/lib/python2.7/site-packages/django/db/backends/mysql/base.py", line 27, in <module>
    raise ImproperlyConfigured("Error loading MySQLdb module: %s" % e)
django.core.exceptions.ImproperlyConfigured: Error loading MySQLdb module: libmysqlclient.so.18: cannot open shared object file: No such file or directory
Unhandled exception in thread started by <function wrapper at 0x7fa338204b90>
Traceback (most recent call last):
  File "/home/joseagraz/Documentos/pdvsaenv/local/lib/python2.7/site-packages/django/utils/autoreload.py", line 229, in wrapper
    fn(*args, **kwargs)
  File "/home/joseagraz/Documentos/pdvsaenv/local/lib/python2.7/site-packages/django/core/management/commands/runserver.py", line 107, in inner_run
    autoreload.raise_last_exception()
  File "/home/joseagraz/Documentos/pdvsaenv/local/lib/python2.7/site-packages/django/utils/autoreload.py", line 252, in raise_last_exception
    six.reraise(*_exception)
  File "/home/joseagraz/Documentos/pdvsaenv/local/lib/python2.7/site-packages/django/utils/autoreload.py", line 229, in wrapper
    fn(*args, **kwargs)
  File "/home/joseagraz/Documentos/pdvsaenv/local/lib/python2.7/site-packages/django/__init__.py", line 18, in setup
    apps.populate(settings.INSTALLED_APPS)
  File "/home/joseagraz/Documentos/pdvsaenv/local/lib/python2.7/site-packages/django/apps/registry.py", line 108, in populate
    app_config.import_models(all_models)
  File "/home/joseagraz/Documentos/pdvsaenv/local/lib/python2.7/site-packages/django/apps/config.py", line 198, in import_models
    self.models_module = import_module(models_module_name)
  File "/usr/lib/python2.7/importlib/__init__.py", line 37, in import_module
    __import__(name)
  File "/home/joseagraz/Documentos/pdvsaenv/local/lib/python2.7/site-packages/django/contrib/auth/models.py", line 41, in <module>
    class Permission(models.Model):
  File "/home/joseagraz/Documentos/pdvsaenv/local/lib/python2.7/site-packages/django/db/models/base.py", line 139, in __new__
    new_class.add_to_class('_meta', Options(meta, **kwargs))
  File "/home/joseagraz/Documentos/pdvsaenv/local/lib/python2.7/site-packages/django/db/models/base.py", line 324, in add_to_class
    value.contribute_to_class(cls, name)
  File "/home/joseagraz/Documentos/pdvsaenv/local/lib/python2.7/site-packages/django/db/models/options.py", line 250, in contribute_to_class
    self.db_table = truncate_name(self.db_table, connection.ops.max_name_length())
  File "/home/joseagraz/Documentos/pdvsaenv/local/lib/python2.7/site-packages/django/db/__init__.py", line 36, in __getattr__
    return getattr(connections[DEFAULT_DB_ALIAS], item)
  File "/home/joseagraz/Documentos/pdvsaenv/local/lib/python2.7/site-packages/django/db/utils.py", line 240, in __getitem__
    backend = load_backend(db['ENGINE'])
  File "/home/joseagraz/Documentos/pdvsaenv/local/lib/python2.7/site-packages/django/db/utils.py", line 111, in load_backend
    return import_module('%s.base' % backend_name)
  File "/usr/lib/python2.7/importlib/__init__.py", line 37, in import_module
    __import__(name)
  File "/home/joseagraz/Documentos/pdvsaenv/local/lib/python2.7/site-packages/django/db/backends/mysql/base.py", line 27, in <module>
    raise ImproperlyConfigured("Error loading MySQLdb module: %s" % e)
django.core.exceptions.ImproperlyConfigured: Error loading MySQLdb module: libmysqlclient.so.18: cannot open shared object file: No such file or directory
/home/joseagraz/Escritorio/envpdvsa/pdvsa-t-d/control/urls.py:14: RemovedInDjango110Warning: django.conf.urls.patterns() is deprecated and will be removed in Django 1.10. Update your urlpatterns to be a list of django.conf.urls.url() instances instead.
  url(r'^(?P<tipo>[^/]+)/resumen/(?P<periodo>[^/]+)/Resumen_anual.xlsx/?$', login_required(ExportExcel_anual.as_view()), name='export_excel_anual'),

/home/joseagraz/Escritorio/envpdvsa/local/lib/python2.7/site-packages/django/template/utils.py:37: RemovedInDjango110Warning: You haven't defined a TEMPLATES setting. You must do so before upgrading to Django 1.10. Otherwise Django will be unable to load templates.
  "unable to load templates.", RemovedInDjango110Warning)

/home/joseagraz/Escritorio/envpdvsa/pdvsa-t-d/pdvsa/urls.py:12: RemovedInDjango110Warning: django.conf.urls.patterns() is deprecated and will be removed in Django 1.10. Update your urlpatterns to be a list of django.conf.urls.url() instances instead.
  url(r'^admin/', include(admin.site.urls)),

[14/Apr/2016 03:41:12] "GET /Login/ HTTP/1.1" 200 2122
[14/Apr/2016 03:41:12] "GET /static/img/logo.png HTTP/1.1" 404 1649
[14/Apr/2016 03:41:17] "POST /Login/ HTTP/1.1" 302 0
[14/Apr/2016 03:41:17] "GET /control HTTP/1.1" 301 0
/home/joseagraz/Escritorio/envpdvsa/local/lib/python2.7/site-packages/django/shortcuts.py:45: RemovedInDjango110Warning: The context_instance argument of render_to_string is deprecated.
  using=using)

[14/Apr/2016 03:41:17] "GET /control/ HTTP/1.1" 200 7862
[14/Apr/2016 03:41:17] "GET /static/img/logo.png HTTP/1.1" 404 1649
[14/Apr/2016 03:41:17] "GET /static/img/chavez1.jpeg HTTP/1.1" 200 22283
[14/Apr/2016 03:41:36] "GET /control/admin/registro/actividades/ HTTP/1.1" 200 9251
[14/Apr/2016 03:41:36] "GET /static/img/logo.png HTTP/1.1" 404 1649
[14/Apr/2016 03:44:48] "GET /control/admin/registro/actividades/ HTTP/1.1" 200 9251
[14/Apr/2016 03:45:01] "GET /static/js/bootstrap-toggle.min.js.map HTTP/1.1" 404 1703
[14/Apr/2016 04:00:57] "GET / HTTP/1.1" 302 0
[14/Apr/2016 04:00:57] "GET /Login/ HTTP/1.1" 302 0
[14/Apr/2016 04:00:57] "GET /control HTTP/1.1" 301 0
[14/Apr/2016 04:00:57] "GET /control/ HTTP/1.1" 200 7862
[14/Apr/2016 04:00:57] "GET /static/img/logo.png HTTP/1.1" 404 1649
[14/Apr/2016 04:01:16] "GET /static/js/bootstrap-toggle.min.js.map HTTP/1.1" 404 1703
